Workbook

Sheet الملخص
A1: توّا — ملخص النموذج المالي
A2: ="السيناريو: "&INDEX({"المتحفظ","الأساسي","المتفائل"},'الافتراضات'!$C$6)&" · غيّره من الافتراضات!C6 · جنيه اسمي بدون ض.ق.م"
A4: المؤشر | B4: 2027 | C4: 2028 | D4: 2029 | E4: 2030 | F4: 2031 | H4: المؤشر الرئيسي | I4: القيمة
A5: طلبات/يوم (ديسمبر) | B5: ='السنوي'!D$13 | C5: ='السنوي'!E$13 | D5: ='السنوي'!F$13 | E5: ='السنوي'!G$13 | F5: ='السنوي'!H$13 | H5: ذروة الاحتياج التمويلي | I5: ='السنوي'!$C$56
A6: العملاء النشطون (ديسمبر) | B6: ='السنوي'!D$8 | C6: ='السنوي'!E$8 | D6: ='السنوي'!F$8 | E6: ='السنوي'!G$8 | F6: ='السنوي'!H$8 | H6: ذروة الاحتياج التمويلي (دولار) | I6: ='السنوي'!$C$56/'الافتراضات'!$C$108
A7: قيمة الطلبات (GMV) | B7: ='السنوي'!D$15 | C7: ='السنوي'!E$15 | D7: ='السنوي'!F$15 | E7: ='السنوي'!G$15 | F7: ='السنوي'!H$15 | H7: جولتا البذرة والنمو في النموذج | I7: ='الافتراضات'!$C$105+'الافتراضات'!$C$106
A8: صافي الإيراد | B8: ='السنوي'!D$27 | C8: ='السنوي'!E$27 | D8: ='السنوي'!F$27 | E8: ='السنوي'!G$27 | F8: ='السنوي'!H$27 | H8: أول شهر مساهمة موجبة | I8: ='السنوي'!$C$58
A9: مجمل الربح | B9: ='السنوي'!D$29 | C9: ='السنوي'!E$29 | D9: ='السنوي'!F$29 | E9: ='السنوي'!G$29 | F9: ='السنوي'!H$29 | H9: أول شهر EBITDA موجبة | I9: ='السنوي'!$C$57
A10: نسبة الاستقطاع (مجمل الربح % من GMV) | B10: ='السنوي'!D$30 | C10: ='السنوي'!E$30 | D10: ='السنوي'!F$30 | E10: ='السنوي'!G$30 | F10: ='السنوي'!H$30 | H10: فحص التمويل | I10: ='السنوي'!$C$60
A11: المساهمة لكل طلب | B11: ='السنوي'!D$37 | C11: ='السنوي'!E$37 | D11: ='السنوي'!F$37 | E11: ='السنوي'!G$37 | F11: ='السنوي'!H$37 | H11: المساهمة مدى الحياة ÷ CAC (السنة 3) | I11: ='السنوي'!$C$63
A12: EBITDA | B12: ='السنوي'!D$42 | C12: ='السنوي'!E$42 | D12: ='السنوي'!F$42 | E12: ='السنوي'!G$42 | F12: ='السنوي'!H$42 | H12: استرداد CAC (السنة 3) | I12: ='السنوي'!$C$64
A13: صافي الدخل | B13: ='السنوي'!D$46 | C13: ='السنوي'!E$46 | D13: ='السنوي'!F$46 | E13: ='السنوي'!G$46 | F13: ='السنوي'!H$46
A14: رصيد النقدية (ديسمبر) | B14: ='السنوي'!D$53 | C14: ='السنوي'!E$53 | D14: ='السنوي'!F$53 | E14: ='السنوي'!G$53 | F14: ='السنوي'!H$53
A18: بيانات الرسم — مجمل الربح حسب المصدر (ج.م)
A19: المصدر | B19: 2027 | C19: 2028 | D19: 2029 | E19: 2030 | F19: 2031
A20: هامش المنتجات | B20: ='مصادر الإيراد'!G4 | C20: ='مصادر الإيراد'!H4 | D20: ='مصادر الإيراد'!I4 | E20: ='مصادر الإيراد'!J4 | F20: ='مصادر الإيراد'!K4
A21: السوق والصيدليات | B21: ='مصادر الإيراد'!G5 | C21: ='مصادر الإيراد'!H5 | D21: ='مصادر الإيراد'!I5 | E21: ='مصادر الإيراد'!J5 | F21: ='مصادر الإيراد'!K5
A22: الأكل | B22: ='مصادر الإيراد'!G6 | C22: ='مصادر الإيراد'!H6 | D22: ='مصادر الإيراد'!I6 | E22: ='مصادر الإيراد'!J6 | F22: ='مصادر الإيراد'!K6
A23: رسوم التوصيل | B23: ='مصادر الإيراد'!G7 | C23: ='مصادر الإيراد'!H7 | D23: ='مصادر الإيراد'!I7 | E23: ='مصادر الإيراد'!J7 | F23: ='مصادر الإيراد'!K7
A24: رسوم الخدمة | B24: ='مصادر الإيراد'!G8 | C24: ='مصادر الإيراد'!H8 | D24: ='مصادر الإيراد'!I8 | E24: ='مصادر الإيراد'!J8 | F24: ='مصادر الإيراد'!K8
A25: توّا+ | B25: ='مصادر الإيراد'!G9 | C25: ='مصادر الإيراد'!H9 | D25: ='مصادر الإيراد'!I9 | E25: ='مصادر الإيراد'!J9 | F25: ='مصادر الإيراد'!K9
A26: التوصيل كخدمة | B26: ='مصادر الإيراد'!G10 | C26: ='مصادر الإيراد'!H10 | D26: ='مصادر الإيراد'!I10 | E26: ='مصادر الإيراد'!J10 | F26: ='مصادر الإيراد'!K10
A27: إعلانات التطبيق | B27: ='مصادر الإيراد'!G11 | C27: ='مصادر الإيراد'!H11 | D27: ='مصادر الإيراد'!I11 | E27: ='مصادر الإيراد'!J11 | F27: ='مصادر الإيراد'!K11
A28: حوافز الموردين | B28: ='مصادر الإيراد'!G12 | C28: ='مصادر الإيراد'!H12 | D28: ='مصادر الإيراد'!I12 | E28: ='مصادر الإيراد'!J12 | F28: ='مصادر الإيراد'!K12
A31: طريقة استخدام النموذج
A32: 1. غيّر المدخلات في ورقة الافتراضات فقط (النص الأزرق؛ الأصفر = الروافع الرئيسية).
A33: 2. بدّل السيناريو من خلية الافتراضات!C6: 1 المتحفظ · 2 الأساسي · 3 المتفائل.
A34: 3. النموذج = محرك شهري (أكتوبر 2026 – ديسمبر 2031). أوراق السنوي واقتصاديات الوحدة ومصادر الإيراد تجمّعه.
A35: 4. الألوان: أزرق مدخل · أسود معادلة · أخضر ربط بورقة أخرى. كل القيم بالجنيه الاسمي بدون ضريبة القيمة المضافة.

Sheet الافتراضات
A1: توّا — الافتراضات (كل المدخلات هنا)
A2: الأزرق = مدخل قابل للتغيير · الأصفر = رافعة رئيسية · القيم بالجنيه الاسمي (تضخم ≈10–12% سنوياً داخل المدخلات السنوية)، بدون ضريبة القيمة المضافة. 2027 = السنة الأولى (تجربة يناير، إطلاق عام فبراير). الأفق: أكتوبر 2026 – ديسمبر 2031.
A5: 1 · السيناريو
A6: السيناريو المختار (1 = المتحفظ، 2 = الأساسي، 3 = المتفائل) | B6: # | C6: 2 | H6: غيّر الخلية دي بس لتبديل النموذج كله.
A7: معامل السيناريو | B7: الوحدة | C7: المتحفظ | D7: الأساسي | E7: المتفائل | F7: نشط | H7: طريقة التطبيق
A8: معامل تكلفة استحواذ العميل | B8: × | C8: 1.25 | D8: 1 | E8: 0.85 | F8: =INDEX(C8:E8,$C$6) | H8: يضرب في CAC السنوي.
A9: تعديل الاحتفاظ الشهري | B9: نقطة | C9: -0.04 | D9: 0 | E9: 0.02 | F9: =INDEX(C9:E9,$C$6) | H9: تُضاف للاحتفاظ السنوي (بحد أقصى 95%).
A10: معامل تكرار الطلب | B10: × | C10: 0.85 | D10: 1 | E10: 1.1 | F10: =INDEX(C10:E10,$C$6) | H10: يضرب في طلبات العميل النشط شهرياً.
A11: معامل حجم السلة (AOV) | B11: × | C11: 0.92 | D11: 1 | E11: 1.05 | F11: =INDEX(C11:E11,$C$6) | H11: يضرب في متوسط قيمة الطلب.
A13: 2 · الجدول الزمني والسوق
A14: المدخل | B14: الوحدة | C14: القيمة | H14: ملاحظة / المصدر
A15: بداية النموذج (أول شهر قبل الإطلاق) | B15: التاريخ | C15: 46296 | H15: أكتوبر–ديسمبر 2026 = بناء ما قبل الإطلاق. يناير 2027 = التجربة (الشهر التشغيلي 1). فبراير 2027 = الإطلاق العام.
A16: سكان مركز أبو المطامير | B16: نسمة | C16: 480000 | H16: تقدير — تحقق من آخر تعداد للجهاز المركزي للتعبئة العامة والإحصاء قبل الاستخدام الخارجي.
A17: متوسط حجم الأسرة | B17: نسمة | C17: 4.6 | H17: تقدير لريف البحيرة؛ تحقق من الجهاز المركزي للتعبئة العامة والإحصاء.
A18: المدخل | B18: الوحدة | C18: 2027 | D18: 2028 | E18: 2029 | F18: 2030 | G18: 2031 | H18: ملاحظة / المصدر
A19: حصة الأسر داخل مناطق التوصيل المفعّلة | B19: % | C19: 0.35 | D19: 0.6 | E19: 0.8 | F19: 0.9 | G19: 0.95 | H19: وسط المدينة أولاً، ثم القرى منطقة منطقة (الهب 2 و3 يوسّعان الوصول).
A20: الهب 2 (هب قرية صغير) يفتح في الشهر التشغيلي | B20: # | C20: 16 | H20: أبريل 2028. التجهيز يُدفع في الشهر السابق.
A21: الهب 3 (هب قرية صغير) يفتح في الشهر التشغيلي | B21: # | C21: 28 | H21: أبريل 2029.
A23: 3 · استحواذ العملاء والاحتفاظ بهم
A24: المدخل | B24: الوحدة | C24: 2027 | D24: 2028 | E24: 2029 | F24: 2030 | G24: 2031 | H24: ملاحظة / المصدر
A25: إنفاق الاستحواذ — شهر التجربة (يناير 2027) | B25: ج.م | C25: 60000 | H25: تجربة بالدعوة: حوالي 400 أسرة، قسائم أول طلب.
A26: إنفاق الاستحواذ — شهر الإطلاق (فبراير 2027) | B26: ج.م | C26: 200000 | H26: دفعة الإطلاق العام: فلاير وجروبات واتساب ومؤثرين وفعاليات إطلاق وخصم 30% على أول طلب.
A27: إنفاق الاستحواذ — الشهر الثالث (مارس 2027) | B27: ج.م | C27: 160000 | H27: الحفاظ على زخم الإطلاق وبدء التشويق في القرى.
A28: إنفاق الاستحواذ — المعدل الشهري بعد ذلك | B28: ج.م/شهر | C28: 120000 | D28: 160000 | E28: 200000 | F28: 230000 | G28: 250000 | H28: استحواذ مدفوع وعروض؛ يزيد مع كل منطقة قرية جديدة.
A29: CAC المجمّع (استحواذ مدفوع شامل خصم أول طلب) | B29: ج.م/عميل | C29: 130 | D29: 150 | E29: 170 | F29: 185 | G29: 200 | H29: افتراض: ترتفع بعد استنفاد المتبنين الأوائل. تتأكد بعد التجربة.
A30: أقصى اختراق ممكن للأسر في نطاق الوصول | B30: % | C30: 0.3 | H30: حد التشبع: استحواذ العملاء الجدد يبطئ خطياً مع اقتراب الاختراق من السقف ده.
A31: العملاء العضويون والإحالة كنسبة من المدفوع | B31: % | C31: 0.2 | D31: 0.3 | E31: 0.35 | F31: 0.38 | G31: 0.4 | H31: إحالة 50 ج.م لكل طرف، كلام الناس، تمييز المناديب.
A32: الاحتفاظ الشهري بالعملاء النشطين | B32: % | C32: 0.72 | D32: 0.78 | E32: 0.81 | F32: 0.83 | G32: 0.84 | H32: نسبة العملاء النشطين الشهر اللي فات اللي طلبوا تاني الشهر ده.
A33: طلبات العميل النشط شهرياً | B33: طلب | C33: 2.8 | D33: 3.3 | E33: 3.7 | F33: 4 | G33: 4.2 | H33: سلوك الطلبات التكميلية: عيش ولبن ومياه وحفاضات أكتر من مرة في الأسبوع.
A35: 4 · السلة ومزيج الأقسام
A36: المدخل | B36: الوحدة | C36: 2027 | D36: 2028 | E36: 2029 | F36: 2030 | G36: 2031 | H36: ملاحظة / المصدر
A37: متوسط قيمة الطلب (AOV) | B37: ج.م | C37: 270 | D37: 315 | E37: 360 | F37: 400 | G37: 440 | H37: اسمي، شامل تضخم حوالي 12% سنوياً ونمو السلة.
A38: مزيج GMV — مخزون توّا المملوك (الهب) | B38: % من GMV | C38: 0.62 | D38: 0.58 | E38: 0.55 | F38: 0.53 | G38: 0.52 | H38: بقالة واحتياجات البيت ومنظفات وعناية شخصية.
A39: مزيج GMV — السوق (تجار محليون وصيدليات شريكة) | B39: % من GMV | C39: 0.13 | D39: 0.15 | E39: 0.17 | F39: 0.18 | G39: 0.19 | H39: أدوية الصيدلية بدون روشتة تُنفّذ عبر صيدليات شريكة مرخّصة.
A40: مزيج GMV — الأكل (مطاعم شريكة ومطبخ توّا) | B40: % من GMV | C40: 0.25 | D40: 0.27 | E40: 0.28 | F40: 0.29 | G40: 0.29
A41: تحقق: مجموع المزيج 100% | C41: =IF(ABS(C38+C39+C40-1)<0.0001,"سليم","خطأ") | D41: =IF(ABS(D38+D39+D40-1)<0.0001,"سليم","خطأ") | E41: =IF(ABS(E38+E39+E40-1)<0.0001,"سليم","خطأ") | F41: =IF(ABS(F38+F39+F40-1)<0.0001,"سليم","خطأ") | G41: =IF(ABS(G38+G39+G40-1)<0.0001,"سليم","خطأ")
A43: 5 · مصادر الإيراد (التسعير ونسب الاستقطاع)
A44: المدخل | B44: الوحدة | C44: 2027 | D44: 2028 | E44: 2029 | F44: 2030 | G44: 2031 | H44: ملاحظة / المصدر
A45: الهامش الأمامي على المخزون المملوك | B45: % من GMV الهب | C45: 0.16 | D45: 0.17 | E45: 0.18 | F45: 0.185 | G45: 0.19 | H45: هامش التجزئة بعد تكلفة الشراء. تجزئة البقالة في مصر عادة 12–20%؛ يتحسن مع الشراء بالكمية والعلامة الخاصة (2029+).
A46: حوافز الموردين (خصومات ورسوم إدراج) | B46: % من GMV الهب | C46: 0 | D46: 0.015 | E46: 0.025 | F46: 0.03 | G46: 0.03 | H46: خصومات كمية من الموزعين والعلامات بعد إثبات الحجم.
...

Sheet النموذج
A1: توّا — النموذج الشهري أكتوبر 2026 – ديسمبر 2031 (معادلات فقط؛ عدّل الافتراضات)
A4: الجدول الزمني
A5: الشهر | C5: ='الافتراضات'!$C$15 | D5: =DATE(YEAR(C5),MONTH(C5)+1,1) | E5: =DATE(YEAR(D5),MONTH(D5)+1,1) | F5: =DATE(YEAR(E5),MONTH(E5)+1,1) | G5: =DATE(YEAR(F5),MONTH(F5)+1,1) | H5: =DATE(YEAR(G5),MONTH(G5)+1,1) | I5: =DATE(YEAR(H5),MONTH(H5)+1,1) | J5: =DATE(YEAR(I5),MONTH(I5)+1,1) | K5: =DATE(YEAR(J5),MONTH(J5)+1,1) | ... BM5: =DATE(YEAR(BL5),MONTH(BL5)+1,1)
A6: السنة الميلادية | C6: =YEAR(C5) | D6: =YEAR(D5) | E6: =YEAR(E5) | F6: =YEAR(F5) | G6: =YEAR(G5) | H6: =YEAR(H5) | I6: =YEAR(I5) | J6: =YEAR(J5) | ... BM6: =YEAR(BM5)
A7: الشهر التشغيلي (1 = تجربة يناير 2027) | B7: # | C7: =(C6-2027)*12+MONTH(C5) | D7: =(D6-2027)*12+MONTH(D5) | E7: =(E6-2027)*12+MONTH(E5) | F7: =(F6-2027)*12+MONTH(F5) | G7: =(G6-2027)*12+MONTH(G5) | H7: =(H6-2027)*12+MONTH(H5) | I7: =(I6-2027)*12+MONTH(I5) | J7: =(J6-2027)*12+MONTH(J5) | ... BM7: =(BM6-2027)*12+MONTH(BM5)
A8: مؤشر التشغيل | B8: 0/1 | C8: =IF(C7>=1,1,0) | D8: =IF(D7>=1,1,0) | E8: =IF(E7>=1,1,0) | F8: =IF(F7>=1,1,0) | G8: =IF(G7>=1,1,0) | H8: =IF(H7>=1,1,0) | I8: =IF(I7>=1,1,0) | J8: =IF(J7>=1,1,0) | ... BM8: =IF(BM7>=1,1,0)
A9: سنة الافتراض (1 = 2027) | B9: # | C9: =MAX(1,MIN(5,C6-2026)) | D9: =MAX(1,MIN(5,D6-2026)) | E9: =MAX(1,MIN(5,E6-2026)) | F9: =MAX(1,MIN(5,F6-2026)) | G9: =MAX(1,MIN(5,G6-2026)) | H9: =MAX(1,MIN(5,H6-2026)) | I9: =MAX(1,MIN(5,I6-2026)) | J9: =MAX(1,MIN(5,J6-2026)) | ... BM9: =MAX(1,MIN(5,BM6-2026))
A10: المرحلة | C10: =IF(C7<1,"ما قبل الإطلاق",IF(C7=1,"تجربة",IF(C7<'الافتراضات'!$C$20,"المدينة",IF(C7<'الافتراضات'!$C$117,"القرى","متعدد المراكز")))) | D10: =IF(D7<1,"ما قبل الإطلاق",IF(D7=1,"تجربة",IF(D7<'الافتراضات'!$C$20,"المدينة",IF(D7<'الافتراضات'!$C$117,"القرى","متعدد المراكز")))) | E10: =IF(E7<1,"ما قبل الإطلاق",IF(E7=1,"تجربة",IF(E7<'الافتراضات'!$C$20,"المدينة",IF(E7<'الافتراضات'!$C$117,"القرى","متعدد المراكز")))) | F10: =IF(F7<1,"ما قبل الإطلاق",IF(F7=1,"تجربة",IF(F7<'الافتراضات'!$C$20,"المدينة",IF(F7<'الافتراضات'!$C$117,"القرى","متعدد المراكز")))) | G10: =IF(G7<1,"ما قبل الإطلاق",IF(G7=1,"تجربة",IF(G7<'الافتراضات'!$C$20,"المدينة",IF(G7<'الافتراضات'!$C$117,"القرى","متعدد المراكز")))) | H10: =IF(H7<1,"ما قبل الإطلاق",IF(H7=1,"تجربة",IF(H7<'الافتراضات'!$C$20,"المدينة",IF(H7<'الافتراضات'!$C$117,"القرى","متعدد المراكز")))) | I10: =IF(I7<1,"ما قبل الإطلاق",IF(I7=1,"تجربة",IF(I7<'الافتراضات'!$C$20,"المدينة",IF(I7<'الافتراضات'!$C$117,"القرى","متعدد المراكز")))) | J10: =IF(J7<1,"ما قبل الإطلاق",IF(J7=1,"تجربة",IF(J7<'الافتراضات'!$C$20,"المدينة",IF(J7<'الافتراضات'!$C$117,"القرى","متعدد المراكز")))) | ... BM10: =IF(BM7<1,"ما قبل الإطلاق",IF(BM7=1,"تجربة",IF(BM7<'الافتراضات'!$C$20,"المدينة",IF(BM7<'الافتراضات'!$C$117,"القرى","متعدد المراكز"))))
A12: العملاء
A13: إنفاق تسويق الاستحواذ — أبو المطامير | B13: ج.م | C13: =C8*IF(C7=1,'الافتراضات'!$C$25,IF(C7=2,'الافتراضات'!$C$26,IF(C7=3,'الافتراضات'!$C$27,INDEX('الافتراضات'!$C$28:$G$28,C$9)))) | D13: =D8*IF(D7=1,'الافتراضات'!$C$25,IF(D7=2,'الافتراضات'!$C$26,IF(D7=3,'الافتراضات'!$C$27,INDEX('الافتراضات'!$C$28:$G$28,D$9)))) | E13: =E8*IF(E7=1,'الافتراضات'!$C$25,IF(E7=2,'الافتراضات'!$C$26,IF(E7=3,'الافتراضات'!$C$27,INDEX('الافتراضات'!$C$28:$G$28,E$9)))) | F13: =F8*IF(F7=1,'الافتراضات'!$C$25,IF(F7=2,'الافتراضات'!$C$26,IF(F7=3,'الافتراضات'!$C$27,INDEX('الافتراضات'!$C$28:$G$28,F$9)))) | G13: =G8*IF(G7=1,'الافتراضات'!$C$25,IF(G7=2,'الافتراضات'!$C$26,IF(G7=3,'الافتراضات'!$C$27,INDEX('الافتراضات'!$C$28:$G$28,G$9)))) | H13: =H8*IF(H7=1,'الافتراضات'!$C$25,IF(H7=2,'الافتراضات'!$C$26,IF(H7=3,'الافتراضات'!$C$27,INDEX('الافتراضات'!$C$28:$G$28,H$9)))) | I13: =I8*IF(I7=1,'الافتراضات'!$C$25,IF(I7=2,'الافتراضات'!$C$26,IF(I7=3,'الافتراضات'!$C$27,INDEX('الافتراضات'!$C$28:$G$28,I$9)))) | J13: =J8*IF(J7=1,'الافتراضات'!$C$25,IF(J7=2,'الافتراضات'!$C$26,IF(J7=3,'الافتراضات'!$C$27,INDEX('الافتراضات'!$C$28:$G$28,J$9)))) | ... BM13: =BM8*IF(BM7=1,'الافتراضات'!$C$25,IF(BM7=2,'الافتراضات'!$C$26,IF(BM7=3,'الافتراضات'!$C$27,INDEX('الافتراضات'!$C$28:$G$28,BM$9))))
A14: CAC المجمّع | B14: ج.م | C14: =INDEX('الافتراضات'!$C$29:$G$29,C$9)*'الافتراضات'!$F$8 | D14: =INDEX('الافتراضات'!$C$29:$G$29,D$9)*'الافتراضات'!$F$8 | E14: =INDEX('الافتراضات'!$C$29:$G$29,E$9)*'الافتراضات'!$F$8 | F14: =INDEX('الافتراضات'!$C$29:$G$29,F$9)*'الافتراضات'!$F$8 | G14: =INDEX('الافتراضات'!$C$29:$G$29,G$9)*'الافتراضات'!$F$8 | H14: =INDEX('الافتراضات'!$C$29:$G$29,H$9)*'الافتراضات'!$F$8 | I14: =INDEX('الافتراضات'!$C$29:$G$29,I$9)*'الافتراضات'!$F$8 | J14: =INDEX('الافتراضات'!$C$29:$G$29,J$9)*'الافتراضات'!$F$8 | ... BM14: =INDEX('الافتراضات'!$C$29:$G$29,BM$9)*'الافتراضات'!$F$8
A15: معامل التشبع (1 = سوق مفتوح) | B15: × | C15: =1 | D15: =MAX(0,1-C22/'الافتراضات'!$C$30) | E15: =MAX(0,1-D22/'الافتراضات'!$C$30) | F15: =MAX(0,1-E22/'الافتراضات'!$C$30) | G15: =MAX(0,1-F22/'الافتراضات'!$C$30) | H15: =MAX(0,1-G22/'الافتراضات'!$C$30) | I15: =MAX(0,1-H22/'الافتراضات'!$C$30) | J15: =MAX(0,1-I22/'الافتراضات'!$C$30) | K15: =MAX(0,1-J22/'الافتراضات'!$C$30) | ... BM15: =MAX(0,1-BL22/'الافتراضات'!$C$30)
A16: العملاء الجدد — مدفوع | B16: # | C16: =IF(C14>0,C13/C14*C15,0) | D16: =IF(D14>0,D13/D14*D15,0) | E16: =IF(E14>0,E13/E14*E15,0) | F16: =IF(F14>0,F13/F14*F15,0) | G16: =IF(G14>0,G13/G14*G15,0) | H16: =IF(H14>0,H13/H14*H15,0) | I16: =IF(I14>0,I13/I14*I15,0) | J16: =IF(J14>0,J13/J14*J15,0) | ... BM16: =IF(BM14>0,BM13/BM14*BM15,0)
A17: العملاء الجدد — عضوي وإحالة | B17: # | C17: =C16*INDEX('الافتراضات'!$C$31:$G$31,C$9) | D17: =D16*INDEX('الافتراضات'!$C$31:$G$31,D$9) | E17: =E16*INDEX('الافتراضات'!$C$31:$G$31,E$9) | F17: =F16*INDEX('الافتراضات'!$C$31:$G$31,F$9) | G17: =G16*INDEX('الافتراضات'!$C$31:$G$31,G$9) | H17: =H16*INDEX('الافتراضات'!$C$31:$G$31,H$9) | I17: =I16*INDEX('الافتراضات'!$C$31:$G$31,I$9) | J17: =J16*INDEX('الافتراضات'!$C$31:$G$31,J$9) | ... BM17: =BM16*INDEX('الافتراضات'!$C$31:$G$31,BM$9)
A18: العملاء الجدد — الإجمالي | B18: # | C18: =C16+C17 | D18: =D16+D17 | E18: =E16+E17 | F18: =F16+F17 | G18: =G16+G17 | H18: =H16+H17 | I18: =I16+I17 | J18: =J16+J17 | ... BM18: =BM16+BM17
A19: الاحتفاظ الشهري | B19: % | C19: =MIN(0.95,INDEX('الافتراضات'!$C$32:$G$32,C$9)+'الافتراضات'!$F$9) | D19: =MIN(0.95,INDEX('الافتراضات'!$C$32:$G$32,D$9)+'الافتراضات'!$F$9) | E19: =MIN(0.95,INDEX('الافتراضات'!$C$32:$G$32,E$9)+'الافتراضات'!$F$9) | F19: =MIN(0.95,INDEX('الافتراضات'!$C$32:$G$32,F$9)+'الافتراضات'!$F$9) | G19: =MIN(0.95,INDEX('الافتراضات'!$C$32:$G$32,G$9)+'الافتراضات'!$F$9) | H19: =MIN(0.95,INDEX('الافتراضات'!$C$32:$G$32,H$9)+'الافتراضات'!$F$9) | I19: =MIN(0.95,INDEX('الافتراضات'!$C$32:$G$32,I$9)+'الافتراضات'!$F$9) | J19: =MIN(0.95,INDEX('الافتراضات'!$C$32:$G$32,J$9)+'الافتراضات'!$F$9) | ... BM19: =MIN(0.95,INDEX('الافتراضات'!$C$32:$G$32,BM$9)+'الافتراضات'!$F$9)
A20: العملاء النشطون — أبو المطامير | B20: # | C20: =C18 | D20: =C20*D19+D18 | E20: =D20*E19+E18 | F20: =E20*F19+F18 | G20: =F20*G19+G18 | H20: =G20*H19+H18 | I20: =H20*I19+I18 | J20: =I20*J19+J18 | K20: =J20*K19+K18 | ... BM20: =BL20*BM19+BM18
A21: الأسر داخل مناطق التوصيل | B21: # | C21: ='الافتراضات'!$C$16/'الافتراضات'!$C$17*INDEX('الافتراضات'!$C$19:$G$19,C$9) | D21: ='الافتراضات'!$C$16/'الافتراضات'!$C$17*INDEX('الافتراضات'!$C$19:$G$19,D$9) | E21: ='الافتراضات'!$C$16/'الافتراضات'!$C$17*INDEX('الافتراضات'!$C$19:$G$19,E$9) | F21: ='الافتراضات'!$C$16/'الافتراضات'!$C$17*INDEX('الافتراضات'!$C$19:$G$19,F$9) | G21: ='الافتراضات'!$C$16/'الافتراضات'!$C$17*INDEX('الافتراضات'!$C$19:$G$19,G$9) | H21: ='الافتراضات'!$C$16/'الافتراضات'!$C$17*INDEX('الافتراضات'!$C$19:$G$19,H$9) | I21: ='الافتراضات'!$C$16/'الافتراضات'!$C$17*INDEX('الافتراضات'!$C$19:$G$19,I$9) | J21: ='الافتراضات'!$C$16/'الافتراضات'!$C$17*INDEX('الافتراضات'!$C$19:$G$19,J$9) | ... BM21: ='الافتراضات'!$C$16/'الافتراضات'!$C$17*INDEX('الافتراضات'!$C$19:$G$19,BM$9)
A22: اختراق الأسر في نطاق الوصول | B22: % | C22: =IF(C21>0,C20/C21,0) | D22: =IF(D21>0,D20/D21,0) | E22: =IF(E21>0,E20/E21,0) | F22: =IF(F21>0,F20/F21,0) | G22: =IF(G21>0,G20/G21,0) | H22: =IF(H21>0,H20/H21,0) | I22: =IF(I21>0,I20/I21,0) | J22: =IF(J21>0,J20/J21,0) | ... BM22: =IF(BM21>0,BM20/BM21,0)
A24: الطلبات و GMV
A25: طلبات العميل النشط شهرياً | B25: # | C25: =INDEX('الافتراضات'!$C$33:$G$33,C$9)*'الافتراضات'!$F$10 | D25: =INDEX('الافتراضات'!$C$33:$G$33,D$9)*'الافتراضات'!$F$10 | E25: =INDEX('الافتراضات'!$C$33:$G$33,E$9)*'الافتراضات'!$F$10 | F25: =INDEX('الافتراضات'!$C$33:$G$33,F$9)*'الافتراضات'!$F$10 | G25: =INDEX('الافتراضات'!$C$33:$G$33,G$9)*'الافتراضات'!$F$10 | H25: =INDEX('الافتراضات'!$C$33:$G$33,H$9)*'الافتراضات'!$F$10 | I25: =INDEX('الافتراضات'!$C$33:$G$33,I$9)*'الافتراضات'!$F$10 | J25: =INDEX('الافتراضات'!$C$33:$G$33,J$9)*'الافتراضات'!$F$10 | ... BM25: =INDEX('الافتراضات'!$C$33:$G$33,BM$9)*'الافتراضات'!$F$10
A26: طلبات العملاء — أبو المطامير | B26: # | C26: =C20*C25 | D26: =D20*D25 | E26: =E20*E25 | F26: =F20*F25 | G26: =G20*G25 | H26: =H20*H25 | I26: =I20*I25 | J26: =J20*J25 | ... BM26: =BM20*BM25
A28: مراكز التوسع (نفس منحنى العمر × معامل الحجم)
A29: العملاء النشطون — حوش عيسى | B29: # | C29: =IF(AND('الافتراضات'!$C$112=1,C7>='الافتراضات'!$C$117),INDEX($C20:$BM20,1,C7-'الافتراضات'!$C$117+4)*'الافتراضات'!$D$117,0) | D29: =IF(AND('الافتراضات'!$C$112=1,D7>='الافتراضات'!$C$117),INDEX($C20:$BM20,1,D7-'الافتراضات'!$C$117+4)*'الافتراضات'!$D$117,0) | E29: =IF(AND('الافتراضات'!$C$112=1,E7>='الافتراضات'!$C$117),INDEX($C20:$BM20,1,E7-'الافتراضات'!$C$117+4)*'الافتراضات'!$D$117,0) | F29: =IF(AND('الافتراضات'!$C$112=1,F7>='الافتراضات'!$C$117),INDEX($C20:$BM20,1,F7-'الافتراضات'!$C$117+4)*'الافتراضات'!$D$117,0) | G29: =IF(AND('الافتراضات'!$C$112=1,G7>='الافتراضات'!$C$117),INDEX($C20:$BM20,1,G7-'الافتراضات'!$C$117+4)*'الافتراضات'!$D$117,0) | H29: =IF(AND('الافتراضات'!$C$112=1,H7>='الافتراضات'!$C$117),INDEX($C20:$BM20,1,H7-'الافتراضات'!$C$117+4)*'الافتراضات'!$D$117,0) | I29: =IF(AND('الافتراضات'!$C$112=1,I7>='الافتراضات'!$C$117),INDEX($C20:$BM20,1,I7-'الافتراضات'!$C$117+4)*'الافتراضات'!$D$117,0) | J29: =IF(AND('الافتراضات'!$C$112=1,J7>='الافتراضات'!$C$117),INDEX($C20:$BM20,1,J7-'الافتراضات'!$C$117+4)*'الافتراضات'!$D$117,0) | ... BM29: =IF(AND('الافتراضات'!$C$112=1,BM7>='الافتراضات'!$C$117),INDEX($C20:$BM20,1,BM7-'الافتراضات'!$C$117+4)*'الافتراضات'!$D$117,0)
A30: العملاء النشطون — أبو حمص | B30: # | C30: =IF(AND('الافتراضات'!$C$112=1,C7>='الافتراضات'!$C$118),INDEX($C20:$BM20,1,C7-'الافتراضات'!$C$118+4)*'الافتراضات'!$D$118,0) | D30: =IF(AND('الافتراضات'!$C$112=1,D7>='الافتراضات'!$C$118),INDEX($C20:$BM20,1,D7-'الافتراضات'!$C$118+4)*'الافتراضات'!$D$118,0) | E30: =IF(AND('الافتراضات'!$C$112=1,E7>='الافتراضات'!$C$118),INDEX($C20:$BM20,1,E7-'الافتراضات'!$C$118+4)*'الافتراضات'!$D$118,0) | F30: =IF(AND('الافتراضات'!$C$112=1,F7>='الافتراضات'!$C$118),INDEX($C20:$BM20,1,F7-'الافتراضات'!$C$118+4)*'الافتراضات'!$D$118,0) | G30: =IF(AND('الافتراضات'!$C$112=1,G7>='الافتراضات'!$C$118),INDEX($C20:$BM20,1,G7-'الافتراضات'!$C$118+4)*'الافتراضات'!$D$118,0) | H30: =IF(AND('الافتراضات'!$C$112=1,H7>='الافتراضات'!$C$118),INDEX($C20:$BM20,1,H7-'الافتراضات'!$C$118+4)*'الافتراضات'!$D$118,0) | I30: =IF(AND('الافتراضات'!$C$112=1,I7>='الافتراضات'!$C$118),INDEX($C20:$BM20,1,I7-'الافتراضات'!$C$118+4)*'الافتراضات'!$D$118,0) | J30: =IF(AND('الافتراضات'!$C$112=1,J7>='الافتراضات'!$C$118),INDEX($C20:$BM20,1,J7-'الافتراضات'!$C$118+4)*'الافتراضات'!$D$118,0) | ... BM30: =IF(AND('الافتراضات'!$C$112=1,BM7>='الافتراضات'!$C$118),INDEX($C20:$BM20,1,BM7-'الافتراضات'!$C$118+4)*'الافتراضات'!$D$118,0)
A31: العملاء النشطون — الدلنجات | B31: # | C31: =IF(AND('الافتراضات'!$C$112=1,C7>='الافتراضات'!$C$119),INDEX($C20:$BM20,1,C7-'الافتراضات'!$C$119+4)*'الافتراضات'!$D$119,0) | D31: =IF(AND('الافتراضات'!$C$112=1,D7>='الافتراضات'!$C$119),INDEX($C20:$BM20,1,D7-'الافتراضات'!$C$119+4)*'الافتراضات'!$D$119,0) | E31: =IF(AND('الافتراضات'!$C$112=1,E7>='الافتراضات'!$C$119),INDEX($C20:$BM20,1,E7-'الافتراضات'!$C$119+4)*'الافتراضات'!$D$119,0) | F31: =IF(AND('الافتراضات'!$C$112=1,F7>='الافتراضات'!$C$119),INDEX($C20:$BM20,1,F7-'الافتراضات'!$C$119+4)*'الافتراضات'!$D$119,0) | G31: =IF(AND('الافتراضات'!$C$112=1,G7>='الافتراضات'!$C$119),INDEX($C20:$BM20,1,G7-'الافتراضات'!$C$119+4)*'الافتراضات'!$D$119,0) | H31: =IF(AND('الافتراضات'!$C$112=1,H7>='الافتراضات'!$C$119),INDEX($C20:$BM20,1,H7-'الافتراضات'!$C$119+4)*'الافتراضات'!$D$119,0) | I31: =IF(AND('الافتراضات'!$C$112=1,I7>='الافتراضات'!$C$119),INDEX($C20:$BM20,1,I7-'الافتراضات'!$C$119+4)*'الافتراضات'!$D$119,0) | J31: =IF(AND('الافتراضات'!$C$112=1,J7>='الافتراضات'!$C$119),INDEX($C20:$BM20,1,J7-'الافتراضات'!$C$119+4)*'الافتراضات'!$D$119,0) | ... BM31: =IF(AND('الافتراضات'!$C$112=1,BM7>='الافتراضات'!$C$119),INDEX($C20:$BM20,1,BM7-'الافتراضات'!$C$119+4)*'الافتراضات'!$D$119,0)
A32: العملاء النشطون — كوم حمادة | B32: # | C32: =IF(AND('الافتراضات'!$C$112=1,C7>='الافتراضات'!$C$120),INDEX($C20:$BM20,1,C7-'الافتراضات'!$C$120+4)*'الافتراضات'!$D$120,0) | D32: =IF(AND('الافتراضات'!$C$112=1,D7>='الافتراضات'!$C$120),INDEX($C20:$BM20,1,D7-'الافتراضات'!$C$120+4)*'الافتراضات'!$D$120,0) | E32: =IF(AND('الافتراضات'!$C$112=1,E7>='الافتراضات'!$C$120),INDEX($C20:$BM20,1,E7-'الافتراضات'!$C$120+4)*'الافتراضات'!$D$120,0) | F32: =IF(AND('الافتراضات'!$C$112=1,F7>='الافتراضات'!$C$120),INDEX($C20:$BM20,1,F7-'الافتراضات'!$C$120+4)*'الافتراضات'!$D$120,0) | G32: =IF(AND('الافتراضات'!$C$112=1,G7>='الافتراضات'!$C$120),INDEX($C20:$BM20,1,G7-'الافتراضات'!$C$120+4)*'الافتراضات'!$D$120,0) | H32: =IF(AND('الافتراضات'!$C$112=1,H7>='الافتراضات'!$C$120),INDEX($C20:$BM20,1,H7-'الافتراضات'!$C$120+4)*'الافتراضات'!$D$120,0) | I32: =IF(AND('الافتراضات'!$C$112=1,I7>='الافتراضات'!$C$120),INDEX($C20:$BM20,1,I7-'الافتراضات'!$C$120+4)*'الافتراضات'!$D$120,0) | J32: =IF(AND('الافتراضات'!$C$112=1,J7>='الافتراضات'!$C$120),INDEX($C20:$BM20,1,J7-'الافتراضات'!$C$120+4)*'الافتراضات'!$D$120,0) | ... BM32: =IF(AND('الافتراضات'!$C$112=1,BM7>='الافتراضات'!$C$120),INDEX($C20:$BM20,1,BM7-'الافتراضات'!$C$120+4)*'الافتراضات'!$D$120,0)
A33: العملاء النشطون — بدر | B33: # | C33: =IF(AND('الافتراضات'!$C$112=1,C7>='الافتراضات'!$C$121),INDEX($C20:$BM20,1,C7-'الافتراضات'!$C$121+4)*'الافتراضات'!$D$121,0) | D33: =IF(AND('الافتراضات'!$C$112=1,D7>='الافتراضات'!$C$121),INDEX($C20:$BM20,1,D7-'الافتراضات'!$C$121+4)*'الافتراضات'!$D$121,0) | E33: =IF(AND('الافتراضات'!$C$112=1,E7>='الافتراضات'!$C$121),INDEX($C20:$BM20,1,E7-'الافتراضات'!$C$121+4)*'الافتراضات'!$D$121,0) | F33: =IF(AND('الافتراضات'!$C$112=1,F7>='الافتراضات'!$C$121),INDEX($C20:$BM20,1,F7-'الافتراضات'!$C$121+4)*'الافتراضات'!$D$121,0) | G33: =IF(AND('الافتراضات'!$C$112=1,G7>='الافتراضات'!$C$121),INDEX($C20:$BM20,1,G7-'الافتراضات'!$C$121+4)*'الافتراضات'!$D$121,0) | H33: =IF(AND('الافتراضات'!$C$112=1,H7>='الافتراضات'!$C$121),INDEX($C20:$BM20,1,H7-'الافتراضات'!$C$121+4)*'الافتراضات'!$D$121,0) | I33: =IF(AND('الافتراضات'!$C$112=1,I7>='الافتراضات'!$C$121),INDEX($C20:$BM20,1,I7-'الافتراضات'!$C$121+4)*'الافتراضات'!$D$121,0) | J33: =IF(AND('الافتراضات'!$C$112=1,J7>='الافتراضات'!$C$121),INDEX($C20:$BM20,1,J7-'الافتراضات'!$C$121+4)*'الافتراضات'!$D$121,0) | ... BM33: =IF(AND('الافتراضات'!$C$112=1,BM7>='الافتراضات'!$C$121),INDEX($C20:$BM20,1,BM7-'الافتراضات'!$C$121+4)*'الافتراضات'!$D$121,0)
A34: العملاء النشطون — (خانة احتياطية) | B34: # | C34: =IF(AND('الافتراضات'!$C$112=1,C7>='الافتراضات'!$C$122),INDEX($C20:$BM20,1,C7-'الافتراضات'!$C$122+4)*'الافتراضات'!$D$122,0) | D34: =IF(AND('الافتراضات'!$C$112=1,D7>='الافتراضات'!$C$122),INDEX($C20:$BM20,1,D7-'الافتراضات'!$C$122+4)*'الافتراضات'!$D$122,0) | E34: =IF(AND('الافتراضات'!$C$112=1,E7>='الافتراضات'!$C$122),INDEX($C20:$BM20,1,E7-'الافتراضات'!$C$122+4)*'الافتراضات'!$D$122,0) | F34: =IF(AND('الافتراضات'!$C$112=1,F7>='الافتراضات'!$C$122),INDEX($C20:$BM20,1,F7-'الافتراضات'!$C$122+4)*'الافتراضات'!$D$122,0) | G34: =IF(AND('الافتراضات'!$C$112=1,G7>='الافتراضات'!$C$122),INDEX($C20:$BM20,1,G7-'الافتراضات'!$C$122+4)*'الافتراضات'!$D$122,0) | H34: =IF(AND('الافتراضات'!$C$112=1,H7>='الافتراضات'!$C$122),INDEX($C20:$BM20,1,H7-'الافتراضات'!$C$122+4)*'الافتراضات'!$D$122,0) | I34: =IF(AND('الافتراضات'!$C$112=1,I7>='الافتراضات'!$C$122),INDEX($C20:$BM20,1,I7-'الافتراضات'!$C$122+4)*'الافتراضات'!$D$122,0) | J34: =IF(AND('الافتراضات'!$C$112=1,J7>='الافتراضات'!$C$122),INDEX($C20:$BM20,1,J7-'الافتراضات'!$C$122+4)*'الافتراضات'!$D$122,0) | ... BM34: =IF(AND('الافتراضات'!$C$112=1,BM7>='الافتراضات'!$C$122),INDEX($C20:$BM20,1,BM7-'الافتراضات'!$C$122+4)*'الافتراضات'!$D$122,0)
A35: الطلبات — حوش عيسى | B35: # | C35: =IF(AND('الافتراضات'!$C$112=1,C7>='الافتراضات'!$C$117),INDEX($C26:$BM26,1,C7-'الافتراضات'!$C$117+4)*'الافتراضات'!$D$117,0) | D35: =IF(AND('الافتراضات'!$C$112=1,D7>='الافتراضات'!$C$117),INDEX($C26:$BM26,1,D7-'الافتراضات'!$C$117+4)*'الافتراضات'!$D$117,0) | E35: =IF(AND('الافتراضات'!$C$112=1,E7>='الافتراضات'!$C$117),INDEX($C26:$BM26,1,E7-'الافتراضات'!$C$117+4)*'الافتراضات'!$D$117,0) | F35: =IF(AND('الافتراضات'!$C$112=1,F7>='الافتراضات'!$C$117),INDEX($C26:$BM26,1,F7-'الافتراضات'!$C$117+4)*'الافتراضات'!$D$117,0) | G35: =IF(AND('الافتراضات'!$C$112=1,G7>='الافتراضات'!$C$117),INDEX($C26:$BM26,1,G7-'الافتراضات'!$C$117+4)*'الافتراضات'!$D$117,0) | H35: =IF(AND('الافتراضات'!$C$112=1,H7>='الافتراضات'!$C$117),INDEX($C26:$BM26,1,H7-'الافتراضات'!$C$117+4)*'الافتراضات'!$D$117,0) | I35: =IF(AND('الافتراضات'!$C$112=1,I7>='الافتراضات'!$C$117),INDEX($C26:$BM26,1,I7-'الافتراضات'!$C$117+4)*'الافتراضات'!$D$117,0) | J35: =IF(AND('الافتراضات'!$C$112=1,J7>='الافتراضات'!$C$117),INDEX($C26:$BM26,1,J7-'الافتراضات'!$C$117+4)*'الافتراضات'!$D$117,0) | ... BM35: =IF(AND('الافتراضات'!$C$112=1,BM7>='الافتراضات'!$C$117),INDEX($C26:$BM26,1,BM7-'الافتراضات'!$C$117+4)*'الافتراضات'!$D$117,0)
A36: الطلبات — أبو حمص | B36: # | C36: =IF(AND('الافتراضات'!$C$112=1,C7>='الافتراضات'!$C$118),INDEX($C26:$BM26,1,C7-'الافتراضات'!$C$118+4)*'الافتراضات'!$D$118,0) | D36: =IF(AND('الافتراضات'!$C$112=1,D7>='الافتراضات'!$C$118),INDEX($C26:$BM26,1,D7-'الافتراضات'!$C$118+4)*'الافتراضات'!$D$118,0) | E36: =IF(AND('الافتراضات'!$C$112=1,E7>='الافتراضات'!$C$118),INDEX($C26:$BM26,1,E7-'الافتراضات'!$C$118+4)*'الافتراضات'!$D$118,0) | F36: =IF(AND('الافتراضات'!$C$112=1,F7>='الافتراضات'!$C$118),INDEX($C26:$BM26,1,F7-'الافتراضات'!$C$118+4)*'الافتراضات'!$D$118,0) | G36: =IF(AND('الافتراضات'!$C$112=1,G7>='الافتراضات'!$C$118),INDEX($C26:$BM26,1,G7-'الافتراضات'!$C$118+4)*'الافتراضات'!$D$118,0) | H36: =IF(AND('الافتراضات'!$C$112=1,H7>='الافتراضات'!$C$118),INDEX($C26:$BM26,1,H7-'الافتراضات'!$C$118+4)*'الافتراضات'!$D$118,0) | I36: =IF(AND('الافتراضات'!$C$112=1,I7>='الافتراضات'!$C$118),INDEX($C26:$BM26,1,I7-'الافتراضات'!$C$118+4)*'الافتراضات'!$D$118,0) | J36: =IF(AND('الافتراضات'!$C$112=1,J7>='الافتراضات'!$C$118),INDEX($C26:$BM26,1,J7-'الافتراضات'!$C$118+4)*'الافتراضات'!$D$118,0) | ... BM36: =IF(AND('الافتراضات'!$C$112=1,BM7>='الافتراضات'!$C$118),INDEX($C26:$BM26,1,BM7-'الافتراضات'!$C$118+4)*'الافتراضات'!$D$118,0)
A37: الطلبات — الدلنجات | B37: # | C37: =IF(AND('الافتراضات'!$C$112=1,C7>='الافتراضات'!$C$119),INDEX($C26:$BM26,1,C7-'الافتراضات'!$C$119+4)*'الافتراضات'!$D$119,0) | D37: =IF(AND('الافتراضات'!$C$112=1,D7>='الافتراضات'!$C$119),INDEX($C26:$BM26,1,D7-'الافتراضات'!$C$119+4)*'الافتراضات'!$D$119,0) | E37: =IF(AND('الافتراضات'!$C$112=1,E7>='الافتراضات'!$C$119),INDEX($C26:$BM26,1,E7-'الافتراضات'!$C$119+4)*'الافتراضات'!$D$119,0) | F37: =IF(AND('الافتراضات'!$C$112=1,F7>='الافتراضات'!$C$119),INDEX($C26:$BM26,1,F7-'الافتراضات'!$C$119+4)*'الافتراضات'!$D$119,0) | G37: =IF(AND('الافتراضات'!$C$112=1,G7>='الافتراضات'!$C$119),INDEX($C26:$BM26,1,G7-'الافتراضات'!$C$119+4)*'الافتراضات'!$D$119,0) | H37: =IF(AND('الافتراضات'!$C$112=1,H7>='الافتراضات'!$C$119),INDEX($C26:$BM26,1,H7-'الافتراضات'!$C$119+4)*'الافتراضات'!$D$119,0) | I37: =IF(AND('الافتراضات'!$C$112=1,I7>='الافتراضات'!$C$119),INDEX($C26:$BM26,1,I7-'الافتراضات'!$C$119+4)*'الافتراضات'!$D$119,0) | J37: =IF(AND('الافتراضات'!$C$112=1,J7>='الافتراضات'!$C$119),INDEX($C26:$BM26,1,J7-'الافتراضات'!$C$119+4)*'الافتراضات'!$D$119,0) | ... BM37: =IF(AND('الافتراضات'!$C$112=1,BM7>='الافتراضات'!$C$119),INDEX($C26:$BM26,1,BM7-'الافتراضات'!$C$119+4)*'الافتراضات'!$D$119,0)
A38: الطلبات — كوم حمادة | B38: # | C38: =IF(AND('الافتراضات'!$C$112=1,C7>='الافتراضات'!$C$120),INDEX($C26:$BM26,1,C7-'الافتراضات'!$C$120+4)*'الافتراضات'!$D$120,0) | D38: =IF(AND('الافتراضات'!$C$112=1,D7>='الافتراضات'!$C$120),INDEX($C26:$BM26,1,D7-'الافتراضات'!$C$120+4)*'الافتراضات'!$D$120,0) | E38: =IF(AND('الافتراضات'!$C$112=1,E7>='الافتراضات'!$C$120),INDEX($C26:$BM26,1,E7-'الافتراضات'!$C$120+4)*'الافتراضات'!$D$120,0) | F38: =IF(AND('الافتراضات'!$C$112=1,F7>='الافتراضات'!$C$120),INDEX($C26:$BM26,1,F7-'الافتراضات'!$C$120+4)*'الافتراضات'!$D$120,0) | G38: =IF(AND('الافتراضات'!$C$112=1,G7>='الافتراضات'!$C$120),INDEX($C26:$BM26,1,G7-'الافتراضات'!$C$120+4)*'الافتراضات'!$D$120,0) | H38: =IF(AND('الافتراضات'!$C$112=1,H7>='الافتراضات'!$C$120),INDEX($C26:$BM26,1,H7-'الافتراضات'!$C$120+4)*'الافتراضات'!$D$120,0) | I38: =IF(AND('الافتراضات'!$C$112=1,I7>='الافتراضات'!$C$120),INDEX($C26:$BM26,1,I7-'الافتراضات'!$C$120+4)*'الافتراضات'!$D$120,0) | J38: =IF(AND('الافتراضات'!$C$112=1,J7>='الافتراضات'!$C$120),INDEX($C26:$BM26,1,J7-'الافتراضات'!$C$120+4)*'الافتراضات'!$D$120,0) | ... BM38: =IF(AND('الافتراضات'!$C$112=1,BM7>='الافتراضات'!$C$120),INDEX($C26:$BM26,1,BM7-'الافتراضات'!$C$120+4)*'الافتراضات'!$D$120,0)
A39: الطلبات — بدر | B39: # | C39: =IF(AND('الافتراضات'!$C$112=1,C7>='الافتراضات'!$C$121),INDEX($C26:$BM26,1,C7-'الافتراضات'!$C$121+4)*'الافتراضات'!$D$121,0) | D39: =IF(AND('الافتراضات'!$C$112=1,D7>='الافتراضات'!$C$121),INDEX($C26:$BM26,1,D7-'الافتراضات'!$C$121+4)*'الافتراضات'!$D$121,0) | E39: =IF(AND('الافتراضات'!$C$112=1,E7>='الافتراضات'!$C$121),INDEX($C26:$BM26,1,E7-'الافتراضات'!$C$121+4)*'الافتراضات'!$D$121,0) | F39: =IF(AND('الافتراضات'!$C$112=1,F7>='الافتراضات'!$C$121),INDEX($C26:$BM26,1,F7-'الافتراضات'!$C$121+4)*'الافتراضات'!$D$121,0) | G39: =IF(AND('الافتراضات'!$C$112=1,G7>='الافتراضات'!$C$121),INDEX($C26:$BM26,1,G7-'الافتراضات'!$C$121+4)*'الافتراضات'!$D$121,0) | H39: =IF(AND('الافتراضات'!$C$112=1,H7>='الافتراضات'!$C$121),INDEX($C26:$BM26,1,H7-'الافتراضات'!$C$121+4)*'الافتراضات'!$D$121,0) | I39: =IF(AND('الافتراضات'!$C$112=1,I7>='الافتراضات'!$C$121),INDEX($C26:$BM26,1,I7-'الافتراضات'!$C$121+4)*'الافتراضات'!$D$121,0) | J39: =IF(AND('الافتراضات'!$C$112=1,J7>='الافتراضات'!$C$121),INDEX($C26:$BM26,1,J7-'الافتراضات'!$C$121+4)*'الافتراضات'!$D$121,0) | ... BM39: =IF(AND('الافتراضات'!$C$112=1,BM7>='الافتراضات'!$C$121),INDEX($C26:$BM26,1,BM7-'الافتراضات'!$C$121+4)*'الافتراضات'!$D$121,0)
A40: الطلبات — (خانة احتياطية) | B40: # | C40: =IF(AND('الافتراضات'!$C$112=1,C7>='الافتراضات'!$C$122),INDEX($C26:$BM26,1,C7-'الافتراضات'!$C$122+4)*'الافتراضات'!$D$122,0) | D40: =IF(AND('الافتراضات'!$C$112=1,D7>='الافتراضات'!$C$122),INDEX($C26:$BM26,1,D7-'الافتراضات'!$C$122+4)*'الافتراضات'!$D$122,0) | E40: =IF(AND('الافتراضات'!$C$112=1,E7>='الافتراضات'!$C$122),INDEX($C26:$BM26,1,E7-'الافتراضات'!$C$122+4)*'الافتراضات'!$D$122,0) | F40: =IF(AND('الافتراضات'!$C$112=1,F7>='الافتراضات'!$C$122),INDEX($C26:$BM26,1,F7-'الافتراضات'!$C$122+4)*'الافتراضات'!$D$122,0) | G40: =IF(AND('الافتراضات'!$C$112=1,G7>='الافتراضات'!$C$122),INDEX($C26:$BM26,1,G7-'الافتراضات'!$C$122+4)*'الافتراضات'!$D$122,0) | H40: =IF(AND('الافتراضات'!$C$112=1,H7>='الافتراضات'!$C$122),INDEX($C26:$BM26,1,H7-'الافتراضات'!$C$122+4)*'الافتراضات'!$D$122,0) | I40: =IF(AND('الافتراضات'!$C$112=1,I7>='الافتراضات'!$C$122),INDEX($C26:$BM26,1,I7-'الافتراضات'!$C$122+4)*'الافتراضات'!$D$122,0) | J40: =IF(AND('الافتراضات'!$C$112=1,J7>='الافتراضات'!$C$122),INDEX($C26:$BM26,1,J7-'الافتراضات'!$C$122+4)*'الافتراضات'!$D$122,0) | ... BM40: =IF(AND('الافتراضات'!$C$112=1,BM7>='الافتراضات'!$C$122),INDEX($C26:$BM26,1,BM7-'الافتراضات'!$C$122+4)*'الافتراضات'!$D$122,0)
A41: إنفاق الاستحواذ — حوش عيسى | B41: ج.م | C41: =IF(AND('الافتراضات'!$C$112=1,C7>='الافتراضات'!$C$117),INDEX($C13:$BM13,1,C7-'الافتراضات'!$C$117+4)*'الافتراضات'!$D$117,0) | D41: =IF(AND('الافتراضات'!$C$112=1,D7>='الافتراضات'!$C$117),INDEX($C13:$BM13,1,D7-'الافتراضات'!$C$117+4)*'الافتراضات'!$D$117,0) | E41: =IF(AND('الافتراضات'!$C$112=1,E7>='الافتراضات'!$C$117),INDEX($C13:$BM13,1,E7-'الافتراضات'!$C$117+4)*'الافتراضات'!$D$117,0) | F41: =IF(AND('الافتراضات'!$C$112=1,F7>='الافتراضات'!$C$117),INDEX($C13:$BM13,1,F7-'الافتراضات'!$C$117+4)*'الافتراضات'!$D$117,0) | G41: =IF(AND('الافتراضات'!$C$112=1,G7>='الافتراضات'!$C$117),INDEX($C13:$BM13,1,G7-'الافتراضات'!$C$117+4)*'الافتراضات'!$D$117,0) | H41: =IF(AND('الافتراضات'!$C$112=1,H7>='الافتراضات'!$C$117),INDEX($C13:$BM13,1,H7-'الافتراضات'!$C$117+4)*'الافتراضات'!$D$117,0) | I41: =IF(AND('الافتراضات'!$C$112=1,I7>='الافتراضات'!$C$117),INDEX($C13:$BM13,1,I7-'الافتراضات'!$C$117+4)*'الافتراضات'!$D$117,0) | J41: =IF(AND('الافتراضات'!$C$112=1,J7>='الافتراضات'!$C$117),INDEX($C13:$BM13,1,J7-'الافتراضات'!$C$117+4)*'الافتراضات'!$D$117,0) | ... BM41: =IF(AND('الافتراضات'!$C$112=1,BM7>='الافتراضات'!$C$117),INDEX($C13:$BM13,1,BM7-'الافتراضات'!$C$117+4)*'الافتراضات'!$D$117,0)
A42: إنفاق الاستحواذ — أبو حمص | B42: ج.م | C42: =IF(AND('الافتراضات'!$C$112=1,C7>='الافتراضات'!$C$118),INDEX($C13:$BM13,1,C7-'الافتراضات'!$C$118+4)*'الافتراضات'!$D$118,0) | D42: =IF(AND('الافتراضات'!$C$112=1,D7>='الافتراضات'!$C$118),INDEX($C13:$BM13,1,D7-'الافتراضات'!$C$118+4)*'الافتراضات'!$D$118,0) | E42: =IF(AND('الافتراضات'!$C$112=1,E7>='الافتراضات'!$C$118),INDEX($C13:$BM13,1,E7-'الافتراضات'!$C$118+4)*'الافتراضات'!$D$118,0) | F42: =IF(AND('الافتراضات'!$C$112=1,F7>='الافتراضات'!$C$118),INDEX($C13:$BM13,1,F7-'الافتراضات'!$C$118+4)*'الافتراضات'!$D$118,0) | G42: =IF(AND('الافتراضات'!$C$112=1,G7>='الافتراضات'!$C$118),INDEX($C13:$BM13,1,G7-'الافتراضات'!$C$118+4)*'الافتراضات'!$D$118,0) | H42: =IF(AND('الافتراضات'!$C$112=1,H7>='الافتراضات'!$C$118),INDEX($C13:$BM13,1,H7-'الافتراضات'!$C$118+4)*'الافتراضات'!$D$118,0) | I42: =IF(AND('الافتراضات'!$C$112=1,I7>='الافتراضات'!$C$118),INDEX($C13:$BM13,1,I7-'الافتراضات'!$C$118+4)*'الافتراضات'!$D$118,0) | J42: =IF(AND('الافتراضات'!$C$112=1,J7>='الافتراضات'!$C$118),INDEX($C13:$BM13,1,J7-'الافتراضات'!$C$118+4)*'الافتراضات'!$D$118,0) | ... BM42: =IF(AND('الافتراضات'!$C$112=1,BM7>='الافتراضات'!$C$118),INDEX($C13:$BM13,1,BM7-'الافتراضات'!$C$118+4)*'الافتراضات'!$D$118,0)
A43: إنفاق الاستحواذ — الدلنجات | B43: ج.م | C43: =IF(AND('الافتراضات'!$C$112=1,C7>='الافتراضات'!$C$119),INDEX($C13:$BM13,1,C7-'الافتراضات'!$C$119+4)*'الافتراضات'!$D$119,0) | D43: =IF(AND('الافتراضات'!$C$112=1,D7>='الافتراضات'!$C$119),INDEX($C13:$BM13,1,D7-'الافتراضات'!$C$119+4)*'الافتراضات'!$D$119,0) | E43: =IF(AND('الافتراضات'!$C$112=1,E7>='الافتراضات'!$C$119),INDEX($C13:$BM13,1,E7-'الافتراضات'!$C$119+4)*'الافتراضات'!$D$119,0) | F43: =IF(AND('الافتراضات'!$C$112=1,F7>='الافتراضات'!$C$119),INDEX($C13:$BM13,1,F7-'الافتراضات'!$C$119+4)*'الافتراضات'!$D$119,0) | G43: =IF(AND('الافتراضات'!$C$112=1,G7>='الافتراضات'!$C$119),INDEX($C13:$BM13,1,G7-'الافتراضات'!$C$119+4)*'الافتراضات'!$D$119,0) | H43: =IF(AND('الافتراضات'!$C$112=1,H7>='الافتراضات'!$C$119),INDEX($C13:$BM13,1,H7-'الافتراضات'!$C$119+4)*'الافتراضات'!$D$119,0) | I43: =IF(AND('الافتراضات'!$C$112=1,I7>='الافتراضات'!$C$119),INDEX($C13:$BM13,1,I7-'الافتراضات'!$C$119+4)*'الافتراضات'!$D$119,0) | J43: =IF(AND('الافتراضات'!$C$112=1,J7>='الافتراضات'!$C$119),INDEX($C13:$BM13,1,J7-'الافتراضات'!$C$119+4)*'الافتراضات'!$D$119,0) | ... BM43: =IF(AND('الافتراضات'!$C$112=1,BM7>='الافتراضات'!$C$119),INDEX($C13:$BM13,1,BM7-'الافتراضات'!$C$119+4)*'الافتراضات'!$D$119,0)
A44: إنفاق الاستحواذ — كوم حمادة | B44: ج.م | C44: =IF(AND('الافتراضات'!$C$112=1,C7>='الافتراضات'!$C$120),INDEX($C13:$BM13,1,C7-'الافتراضات'!$C$120+4)*'الافتراضات'!$D$120,0) | D44: =IF(AND('الافتراضات'!$C$112=1,D7>='الافتراضات'!$C$120),INDEX($C13:$BM13,1,D7-'الافتراضات'!$C$120+4)*'الافتراضات'!$D$120,0) | E44: =IF(AND('الافتراضات'!$C$112=1,E7>='الافتراضات'!$C$120),INDEX($C13:$BM13,1,E7-'الافتراضات'!$C$120+4)*'الافتراضات'!$D$120,0) | F44: =IF(AND('الافتراضات'!$C$112=1,F7>='الافتراضات'!$C$120),INDEX($C13:$BM13,1,F7-'الافتراضات'!$C$120+4)*'الافتراضات'!$D$120,0) | G44: =IF(AND('الافتراضات'!$C$112=1,G7>='الافتراضات'!$C$120),INDEX($C13:$BM13,1,G7-'الافتراضات'!$C$120+4)*'الافتراضات'!$D$120,0) | H44: =IF(AND('الافتراضات'!$C$112=1,H7>='الافتراضات'!$C$120),INDEX($C13:$BM13,1,H7-'الافتراضات'!$C$120+4)*'الافتراضات'!$D$120,0) | I44: =IF(AND('الافتراضات'!$C$112=1,I7>='الافتراضات'!$C$120),INDEX($C13:$BM13,1,I7-'الافتراضات'!$C$120+4)*'الافتراضات'!$D$120,0) | J44: =IF(AND('الافتراضات'!$C$112=1,J7>='الافتراضات'!$C$120),INDEX($C13:$BM13,1,J7-'الافتراضات'!$C$120+4)*'الافتراضات'!$D$120,0) | ... BM44: =IF(AND('الافتراضات'!$C$112=1,BM7>='الافتراضات'!$C$120),INDEX($C13:$BM13,1,BM7-'الافتراضات'!$C$120+4)*'الافتراضات'!$D$120,0)
A45: إنفاق الاستحواذ — بدر | B45: ج.م | C45: =IF(AND('الافتراضات'!$C$112=1,C7>='الافتراضات'!$C$121),INDEX($C13:$BM13,1,C7-'الافتراضات'!$C$121+4)*'الافتراضات'!$D$121,0) | D45: =IF(AND('الافتراضات'!$C$112=1,D7>='الافتراضات'!$C$121),INDEX($C13:$BM13,1,D7-'الافتراضات'!$C$121+4)*'الافتراضات'!$D$121,0) | E45: =IF(AND('الافتراضات'!$C$112=1,E7>='الافتراضات'!$C$121),INDEX($C13:$BM13,1,E7-'الافتراضات'!$C$121+4)*'الافتراضات'!$D$121,0) | F45: =IF(AND('الافتراضات'!$C$112=1,F7>='الافتراضات'!$C$121),INDEX($C13:$BM13,1,F7-'الافتراضات'!$C$121+4)*'الافتراضات'!$D$121,0) | G45: =IF(AND('الافتراضات'!$C$112=1,G7>='الافتراضات'!$C$121),INDEX($C13:$BM13,1,G7-'الافتراضات'!$C$121+4)*'الافتراضات'!$D$121,0) | H45: =IF(AND('الافتراضات'!$C$112=1,H7>='الافتراضات'!$C$121),INDEX($C13:$BM13,1,H7-'الافتراضات'!$C$121+4)*'الافتراضات'!$D$121,0) | I45: =IF(AND('الافتراضات'!$C$112=1,I7>='الافتراضات'!$C$121),INDEX($C13:$BM13,1,I7-'الافتراضات'!$C$121+4)*'الافتراضات'!$D$121,0) | J45: =IF(AND('الافتراضات'!$C$112=1,J7>='الافتراضات'!$C$121),INDEX($C13:$BM13,1,J7-'الافتراضات'!$C$121+4)*'الافتراضات'!$D$121,0) | ... BM45: =IF(AND('الافتراضات'!$C$112=1,BM7>='الافتراضات'!$C$121),INDEX($C13:$BM13,1,BM7-'الافتراضات'!$C$121+4)*'الافتراضات'!$D$121,0)
...

Sheet السنوي
A1: توّا — الملخص السنوي (ج.م، اسمي)
A2: السنة | C2: 2026 | D2: 2027 | E2: 2028 | F2: 2029 | G2: 2030 | H2: 2031
C3: ما قبل الإطلاق | D3: السنة 1 | E3: السنة 2 | F3: السنة 3 | G3: السنة 4 | H3: السنة 5
A5: العملاء والحجم
A6: المراكز العاملة (ديسمبر) | C6: =IFERROR(INDEX('النموذج'!$C$51:$BM$51,MATCH(DATE(2026,12,1),'النموذج'!$C$5:$BM$5,0)),0) | D6: =IFERROR(INDEX('النموذج'!$C$51:$BM$51,MATCH(DATE(2027,12,1),'النموذج'!$C$5:$BM$5,0)),0) | E6: =IFERROR(INDEX('النموذج'!$C$51:$BM$51,MATCH(DATE(2028,12,1),'النموذج'!$C$5:$BM$5,0)),0) | F6: =IFERROR(INDEX('النموذج'!$C$51:$BM$51,MATCH(DATE(2029,12,1),'النموذج'!$C$5:$BM$5,0)),0) | G6: =IFERROR(INDEX('النموذج'!$C$51:$BM$51,MATCH(DATE(2030,12,1),'النموذج'!$C$5:$BM$5,0)),0) | H6: =IFERROR(INDEX('النموذج'!$C$51:$BM$51,MATCH(DATE(2031,12,1),'النموذج'!$C$5:$BM$5,0)),0)
A7: الهبات العاملة (ديسمبر) | C7: =IFERROR(INDEX('النموذج'!$C$94:$BM$94,MATCH(DATE(2026,12,1),'النموذج'!$C$5:$BM$5,0)),0) | D7: =IFERROR(INDEX('النموذج'!$C$94:$BM$94,MATCH(DATE(2027,12,1),'النموذج'!$C$5:$BM$5,0)),0) | E7: =IFERROR(INDEX('النموذج'!$C$94:$BM$94,MATCH(DATE(2028,12,1),'النموذج'!$C$5:$BM$5,0)),0) | F7: =IFERROR(INDEX('النموذج'!$C$94:$BM$94,MATCH(DATE(2029,12,1),'النموذج'!$C$5:$BM$5,0)),0) | G7: =IFERROR(INDEX('النموذج'!$C$94:$BM$94,MATCH(DATE(2030,12,1),'النموذج'!$C$5:$BM$5,0)),0) | H7: =IFERROR(INDEX('النموذج'!$C$94:$BM$94,MATCH(DATE(2031,12,1),'النموذج'!$C$5:$BM$5,0)),0)
A8: العملاء النشطون (ديسمبر) | C8: =IFERROR(INDEX('النموذج'!$C$52:$BM$52,MATCH(DATE(2026,12,1),'النموذج'!$C$5:$BM$5,0)),0) | D8: =IFERROR(INDEX('النموذج'!$C$52:$BM$52,MATCH(DATE(2027,12,1),'النموذج'!$C$5:$BM$5,0)),0) | E8: =IFERROR(INDEX('النموذج'!$C$52:$BM$52,MATCH(DATE(2028,12,1),'النموذج'!$C$5:$BM$5,0)),0) | F8: =IFERROR(INDEX('النموذج'!$C$52:$BM$52,MATCH(DATE(2029,12,1),'النموذج'!$C$5:$BM$5,0)),0) | G8: =IFERROR(INDEX('النموذج'!$C$52:$BM$52,MATCH(DATE(2030,12,1),'النموذج'!$C$5:$BM$5,0)),0) | H8: =IFERROR(INDEX('النموذج'!$C$52:$BM$52,MATCH(DATE(2031,12,1),'النموذج'!$C$5:$BM$5,0)),0)
A9: منها أبو المطامير | C9: =IFERROR(INDEX('النموذج'!$C$20:$BM$20,MATCH(DATE(2026,12,1),'النموذج'!$C$5:$BM$5,0)),0) | D9: =IFERROR(INDEX('النموذج'!$C$20:$BM$20,MATCH(DATE(2027,12,1),'النموذج'!$C$5:$BM$5,0)),0) | E9: =IFERROR(INDEX('النموذج'!$C$20:$BM$20,MATCH(DATE(2028,12,1),'النموذج'!$C$5:$BM$5,0)),0) | F9: =IFERROR(INDEX('النموذج'!$C$20:$BM$20,MATCH(DATE(2029,12,1),'النموذج'!$C$5:$BM$5,0)),0) | G9: =IFERROR(INDEX('النموذج'!$C$20:$BM$20,MATCH(DATE(2030,12,1),'النموذج'!$C$5:$BM$5,0)),0) | H9: =IFERROR(INDEX('النموذج'!$C$20:$BM$20,MATCH(DATE(2031,12,1),'النموذج'!$C$5:$BM$5,0)),0)
A10: العملاء الجدد المكتسبون | C10: =SUMIF('النموذج'!$C$6:$BM$6,2026,'النموذج'!$C$18:$BM$18) | D10: =SUMIF('النموذج'!$C$6:$BM$6,2027,'النموذج'!$C$18:$BM$18) | E10: =SUMIF('النموذج'!$C$6:$BM$6,2028,'النموذج'!$C$18:$BM$18) | F10: =SUMIF('النموذج'!$C$6:$BM$6,2029,'النموذج'!$C$18:$BM$18) | G10: =SUMIF('النموذج'!$C$6:$BM$6,2030,'النموذج'!$C$18:$BM$18) | H10: =SUMIF('النموذج'!$C$6:$BM$6,2031,'النموذج'!$C$18:$BM$18)
A11: طلبات العملاء | C11: =SUMIF('النموذج'!$C$6:$BM$6,2026,'النموذج'!$C$54:$BM$54) | D11: =SUMIF('النموذج'!$C$6:$BM$6,2027,'النموذج'!$C$54:$BM$54) | E11: =SUMIF('النموذج'!$C$6:$BM$6,2028,'النموذج'!$C$54:$BM$54) | F11: =SUMIF('النموذج'!$C$6:$BM$6,2029,'النموذج'!$C$54:$BM$54) | G11: =SUMIF('النموذج'!$C$6:$BM$6,2030,'النموذج'!$C$54:$BM$54) | H11: =SUMIF('النموذج'!$C$6:$BM$6,2031,'النموذج'!$C$54:$BM$54)
A12: منها أبو المطامير | C12: =SUMIF('النموذج'!$C$6:$BM$6,2026,'النموذج'!$C$26:$BM$26) | D12: =SUMIF('النموذج'!$C$6:$BM$6,2027,'النموذج'!$C$26:$BM$26) | E12: =SUMIF('النموذج'!$C$6:$BM$6,2028,'النموذج'!$C$26:$BM$26) | F12: =SUMIF('النموذج'!$C$6:$BM$6,2029,'النموذج'!$C$26:$BM$26) | G12: =SUMIF('النموذج'!$C$6:$BM$6,2030,'النموذج'!$C$26:$BM$26) | H12: =SUMIF('النموذج'!$C$6:$BM$6,2031,'النموذج'!$C$26:$BM$26)
A13: طلبات/يوم (ديسمبر) | C13: =IFERROR(INDEX('النموذج'!$C$55:$BM$55,MATCH(DATE(2026,12,1),'النموذج'!$C$5:$BM$5,0)),0) | D13: =IFERROR(INDEX('النموذج'!$C$55:$BM$55,MATCH(DATE(2027,12,1),'النموذج'!$C$5:$BM$5,0)),0) | E13: =IFERROR(INDEX('النموذج'!$C$55:$BM$55,MATCH(DATE(2028,12,1),'النموذج'!$C$5:$BM$5,0)),0) | F13: =IFERROR(INDEX('النموذج'!$C$55:$BM$55,MATCH(DATE(2029,12,1),'النموذج'!$C$5:$BM$5,0)),0) | G13: =IFERROR(INDEX('النموذج'!$C$55:$BM$55,MATCH(DATE(2030,12,1),'النموذج'!$C$5:$BM$5,0)),0) | H13: =IFERROR(INDEX('النموذج'!$C$55:$BM$55,MATCH(DATE(2031,12,1),'النموذج'!$C$5:$BM$5,0)),0)
A14: توصيلات التوصيل كخدمة | C14: =SUMIF('النموذج'!$C$6:$BM$6,2026,'النموذج'!$C$56:$BM$56) | D14: =SUMIF('النموذج'!$C$6:$BM$6,2027,'النموذج'!$C$56:$BM$56) | E14: =SUMIF('النموذج'!$C$6:$BM$6,2028,'النموذج'!$C$56:$BM$56) | F14: =SUMIF('النموذج'!$C$6:$BM$6,2029,'النموذج'!$C$56:$BM$56) | G14: =SUMIF('النموذج'!$C$6:$BM$6,2030,'النموذج'!$C$56:$BM$56) | H14: =SUMIF('النموذج'!$C$6:$BM$6,2031,'النموذج'!$C$56:$BM$56)
A15: قيمة الطلبات (GMV) | C15: =SUMIF('النموذج'!$C$6:$BM$6,2026,'النموذج'!$C$58:$BM$58) | D15: =SUMIF('النموذج'!$C$6:$BM$6,2027,'النموذج'!$C$58:$BM$58) | E15: =SUMIF('النموذج'!$C$6:$BM$6,2028,'النموذج'!$C$58:$BM$58) | F15: =SUMIF('النموذج'!$C$6:$BM$6,2029,'النموذج'!$C$58:$BM$58) | G15: =SUMIF('النموذج'!$C$6:$BM$6,2030,'النموذج'!$C$58:$BM$58) | H15: =SUMIF('النموذج'!$C$6:$BM$6,2031,'النموذج'!$C$58:$BM$58)
A17: مصادر الإيراد
A18: 1. مبيعات المنتجات (مخزون مملوك) | C18: =SUMIF('النموذج'!$C$6:$BM$6,2026,'النموذج'!$C$64:$BM$64) | D18: =SUMIF('النموذج'!$C$6:$BM$6,2027,'النموذج'!$C$64:$BM$64) | E18: =SUMIF('النموذج'!$C$6:$BM$6,2028,'النموذج'!$C$64:$BM$64) | F18: =SUMIF('النموذج'!$C$6:$BM$6,2029,'النموذج'!$C$64:$BM$64) | G18: =SUMIF('النموذج'!$C$6:$BM$6,2030,'النموذج'!$C$64:$BM$64) | H18: =SUMIF('النموذج'!$C$6:$BM$6,2031,'النموذج'!$C$64:$BM$64)
A19: 2. عمولة السوق والصيدليات | C19: =SUMIF('النموذج'!$C$6:$BM$6,2026,'النموذج'!$C$65:$BM$65) | D19: =SUMIF('النموذج'!$C$6:$BM$6,2027,'النموذج'!$C$65:$BM$65) | E19: =SUMIF('النموذج'!$C$6:$BM$6,2028,'النموذج'!$C$65:$BM$65) | F19: =SUMIF('النموذج'!$C$6:$BM$6,2029,'النموذج'!$C$65:$BM$65) | G19: =SUMIF('النموذج'!$C$6:$BM$6,2030,'النموذج'!$C$65:$BM$65) | H19: =SUMIF('النموذج'!$C$6:$BM$6,2031,'النموذج'!$C$65:$BM$65)
A20: 3. عمولة المطاعم | C20: =SUMIF('النموذج'!$C$6:$BM$6,2026,'النموذج'!$C$66:$BM$66) | D20: =SUMIF('النموذج'!$C$6:$BM$6,2027,'النموذج'!$C$66:$BM$66) | E20: =SUMIF('النموذج'!$C$6:$BM$6,2028,'النموذج'!$C$66:$BM$66) | F20: =SUMIF('النموذج'!$C$6:$BM$6,2029,'النموذج'!$C$66:$BM$66) | G20: =SUMIF('النموذج'!$C$6:$BM$6,2030,'النموذج'!$C$66:$BM$66) | H20: =SUMIF('النموذج'!$C$6:$BM$6,2031,'النموذج'!$C$66:$BM$66)
A21: 4. رسوم التوصيل | C21: =SUMIF('النموذج'!$C$6:$BM$6,2026,'النموذج'!$C$68:$BM$68) | D21: =SUMIF('النموذج'!$C$6:$BM$6,2027,'النموذج'!$C$68:$BM$68) | E21: =SUMIF('النموذج'!$C$6:$BM$6,2028,'النموذج'!$C$68:$BM$68) | F21: =SUMIF('النموذج'!$C$6:$BM$6,2029,'النموذج'!$C$68:$BM$68) | G21: =SUMIF('النموذج'!$C$6:$BM$6,2030,'النموذج'!$C$68:$BM$68) | H21: =SUMIF('النموذج'!$C$6:$BM$6,2031,'النموذج'!$C$68:$BM$68)
A22: 5. رسوم الخدمة | C22: =SUMIF('النموذج'!$C$6:$BM$6,2026,'النموذج'!$C$69:$BM$69) | D22: =SUMIF('النموذج'!$C$6:$BM$6,2027,'النموذج'!$C$69:$BM$69) | E22: =SUMIF('النموذج'!$C$6:$BM$6,2028,'النموذج'!$C$69:$BM$69) | F22: =SUMIF('النموذج'!$C$6:$BM$6,2029,'النموذج'!$C$69:$BM$69) | G22: =SUMIF('النموذج'!$C$6:$BM$6,2030,'النموذج'!$C$69:$BM$69) | H22: =SUMIF('النموذج'!$C$6:$BM$6,2031,'النموذج'!$C$69:$BM$69)
A23: 6. اشتراكات توّا+ | C23: =SUMIF('النموذج'!$C$6:$BM$6,2026,'النموذج'!$C$70:$BM$70) | D23: =SUMIF('النموذج'!$C$6:$BM$6,2027,'النموذج'!$C$70:$BM$70) | E23: =SUMIF('النموذج'!$C$6:$BM$6,2028,'النموذج'!$C$70:$BM$70) | F23: =SUMIF('النموذج'!$C$6:$BM$6,2029,'النموذج'!$C$70:$BM$70) | G23: =SUMIF('النموذج'!$C$6:$BM$6,2030,'النموذج'!$C$70:$BM$70) | H23: =SUMIF('النموذج'!$C$6:$BM$6,2031,'النموذج'!$C$70:$BM$70)
A24: 7. رسوم التوصيل كخدمة | C24: =SUMIF('النموذج'!$C$6:$BM$6,2026,'النموذج'!$C$71:$BM$71) | D24: =SUMIF('النموذج'!$C$6:$BM$6,2027,'النموذج'!$C$71:$BM$71) | E24: =SUMIF('النموذج'!$C$6:$BM$6,2028,'النموذج'!$C$71:$BM$71) | F24: =SUMIF('النموذج'!$C$6:$BM$6,2029,'النموذج'!$C$71:$BM$71) | G24: =SUMIF('النموذج'!$C$6:$BM$6,2030,'النموذج'!$C$71:$BM$71) | H24: =SUMIF('النموذج'!$C$6:$BM$6,2031,'النموذج'!$C$71:$BM$71)
A25: 8. إعلانات التطبيق | C25: =SUMIF('النموذج'!$C$6:$BM$6,2026,'النموذج'!$C$72:$BM$72) | D25: =SUMIF('النموذج'!$C$6:$BM$6,2027,'النموذج'!$C$72:$BM$72) | E25: =SUMIF('النموذج'!$C$6:$BM$6,2028,'النموذج'!$C$72:$BM$72) | F25: =SUMIF('النموذج'!$C$6:$BM$6,2029,'النموذج'!$C$72:$BM$72) | G25: =SUMIF('النموذج'!$C$6:$BM$6,2030,'النموذج'!$C$72:$BM$72) | H25: =SUMIF('النموذج'!$C$6:$BM$6,2031,'النموذج'!$C$72:$BM$72)
A26: 9. حوافز الموردين | C26: =SUMIF('النموذج'!$C$6:$BM$6,2026,'النموذج'!$C$73:$BM$73) | D26: =SUMIF('النموذج'!$C$6:$BM$6,2027,'النموذج'!$C$73:$BM$73) | E26: =SUMIF('النموذج'!$C$6:$BM$6,2028,'النموذج'!$C$73:$BM$73) | F26: =SUMIF('النموذج'!$C$6:$BM$6,2029,'النموذج'!$C$73:$BM$73) | G26: =SUMIF('النموذج'!$C$6:$BM$6,2030,'النموذج'!$C$73:$BM$73) | H26: =SUMIF('النموذج'!$C$6:$BM$6,2031,'النموذج'!$C$73:$BM$73)
A27: صافي الإيراد | C27: =SUMIF('النموذج'!$C$6:$BM$6,2026,'النموذج'!$C$74:$BM$74) | D27: =SUMIF('النموذج'!$C$6:$BM$6,2027,'النموذج'!$C$74:$BM$74) | E27: =SUMIF('النموذج'!$C$6:$BM$6,2028,'النموذج'!$C$74:$BM$74) | F27: =SUMIF('النموذج'!$C$6:$BM$6,2029,'النموذج'!$C$74:$BM$74) | G27: =SUMIF('النموذج'!$C$6:$BM$6,2030,'النموذج'!$C$74:$BM$74) | H27: =SUMIF('النموذج'!$C$6:$BM$6,2031,'النموذج'!$C$74:$BM$74)
A28: تكلفة البضاعة المباعة | C28: =SUMIF('النموذج'!$C$6:$BM$6,2026,'النموذج'!$C$75:$BM$75) | D28: =SUMIF('النموذج'!$C$6:$BM$6,2027,'النموذج'!$C$75:$BM$75) | E28: =SUMIF('النموذج'!$C$6:$BM$6,2028,'النموذج'!$C$75:$BM$75) | F28: =SUMIF('النموذج'!$C$6:$BM$6,2029,'النموذج'!$C$75:$BM$75) | G28: =SUMIF('النموذج'!$C$6:$BM$6,2030,'النموذج'!$C$75:$BM$75) | H28: =SUMIF('النموذج'!$C$6:$BM$6,2031,'النموذج'!$C$75:$BM$75)
A29: مجمل الربح | C29: =SUMIF('النموذج'!$C$6:$BM$6,2026,'النموذج'!$C$76:$BM$76) | D29: =SUMIF('النموذج'!$C$6:$BM$6,2027,'النموذج'!$C$76:$BM$76) | E29: =SUMIF('النموذج'!$C$6:$BM$6,2028,'النموذج'!$C$76:$BM$76) | F29: =SUMIF('النموذج'!$C$6:$BM$6,2029,'النموذج'!$C$76:$BM$76) | G29: =SUMIF('النموذج'!$C$6:$BM$6,2030,'النموذج'!$C$76:$BM$76) | H29: =SUMIF('النموذج'!$C$6:$BM$6,2031,'النموذج'!$C$76:$BM$76)
A30: مجمل الربح % من GMV (نسبة الاستقطاع) | C30: =IF(C15>0,C29/C15,0) | D30: =IF(D15>0,D29/D15,0) | E30: =IF(E15>0,E29/E15,0) | F30: =IF(F15>0,F29/F15,0) | G30: =IF(G15>0,G29/G15,0) | H30: =IF(H15>0,H29/H15,0)
A32: التكاليف والربحية
A33: التكاليف المتغيرة | C33: =SUMIF('النموذج'!$C$6:$BM$6,2026,'النموذج'!$C$89:$BM$89) | D33: =SUMIF('النموذج'!$C$6:$BM$6,2027,'النموذج'!$C$89:$BM$89) | E33: =SUMIF('النموذج'!$C$6:$BM$6,2028,'النموذج'!$C$89:$BM$89) | F33: =SUMIF('النموذج'!$C$6:$BM$6,2029,'النموذج'!$C$89:$BM$89) | G33: =SUMIF('النموذج'!$C$6:$BM$6,2030,'النموذج'!$C$89:$BM$89) | H33: =SUMIF('النموذج'!$C$6:$BM$6,2031,'النموذج'!$C$89:$BM$89)
A34: منها تكلفة المندوب | C34: =SUMIF('النموذج'!$C$6:$BM$6,2026,'النموذج'!$C$81:$BM$81) | D34: =SUMIF('النموذج'!$C$6:$BM$6,2027,'النموذج'!$C$81:$BM$81) | E34: =SUMIF('النموذج'!$C$6:$BM$6,2028,'النموذج'!$C$81:$BM$81) | F34: =SUMIF('النموذج'!$C$6:$BM$6,2029,'النموذج'!$C$81:$BM$81) | G34: =SUMIF('النموذج'!$C$6:$BM$6,2030,'النموذج'!$C$81:$BM$81) | H34: =SUMIF('النموذج'!$C$6:$BM$6,2031,'النموذج'!$C$81:$BM$81)
A35: منها عروض العملاء | C35: =SUMIF('النموذج'!$C$6:$BM$6,2026,'النموذج'!$C$85:$BM$85) | D35: =SUMIF('النموذج'!$C$6:$BM$6,2027,'النموذج'!$C$85:$BM$85) | E35: =SUMIF('النموذج'!$C$6:$BM$6,2028,'النموذج'!$C$85:$BM$85) | F35: =SUMIF('النموذج'!$C$6:$BM$6,2029,'النموذج'!$C$85:$BM$85) | G35: =SUMIF('النموذج'!$C$6:$BM$6,2030,'النموذج'!$C$85:$BM$85) | H35: =SUMIF('النموذج'!$C$6:$BM$6,2031,'النموذج'!$C$85:$BM$85)
A36: هامش المساهمة | C36: =SUMIF('النموذج'!$C$6:$BM$6,2026,'النموذج'!$C$90:$BM$90) | D36: =SUMIF('النموذج'!$C$6:$BM$6,2027,'النموذج'!$C$90:$BM$90) | E36: =SUMIF('النموذج'!$C$6:$BM$6,2028,'النموذج'!$C$90:$BM$90) | F36: =SUMIF('النموذج'!$C$6:$BM$6,2029,'النموذج'!$C$90:$BM$90) | G36: =SUMIF('النموذج'!$C$6:$BM$6,2030,'النموذج'!$C$90:$BM$90) | H36: =SUMIF('النموذج'!$C$6:$BM$6,2031,'النموذج'!$C$90:$BM$90)
A37: المساهمة لكل طلب | C37: =IF(C11>0,C36/C11,0) | D37: =IF(D11>0,D36/D11,0) | E37: =IF(E11>0,E36/E11,0) | F37: =IF(F11>0,F36/F11,0) | G37: =IF(G11>0,G36/G11,0) | H37: =IF(H11>0,H36/H11,0)
A38: المصروفات التشغيلية (شامل الاستحواذ) | C38: =SUMIF('النموذج'!$C$6:$BM$6,2026,'النموذج'!$C$104:$BM$104) | D38: =SUMIF('النموذج'!$C$6:$BM$6,2027,'النموذج'!$C$104:$BM$104) | E38: =SUMIF('النموذج'!$C$6:$BM$6,2028,'النموذج'!$C$104:$BM$104) | F38: =SUMIF('النموذج'!$C$6:$BM$6,2029,'النموذج'!$C$104:$BM$104) | G38: =SUMIF('النموذج'!$C$6:$BM$6,2030,'النموذج'!$C$104:$BM$104) | H38: =SUMIF('النموذج'!$C$6:$BM$6,2031,'النموذج'!$C$104:$BM$104)
A39: منها تسويق الاستحواذ | C39: =SUMIF('النموذج'!$C$6:$BM$6,2026,'النموذج'!$C$103:$BM$103) | D39: =SUMIF('النموذج'!$C$6:$BM$6,2027,'النموذج'!$C$103:$BM$103) | E39: =SUMIF('النموذج'!$C$6:$BM$6,2028,'النموذج'!$C$103:$BM$103) | F39: =SUMIF('النموذج'!$C$6:$BM$6,2029,'النموذج'!$C$103:$BM$103) | G39: =SUMIF('النموذج'!$C$6:$BM$6,2030,'النموذج'!$C$103:$BM$103) | H39: =SUMIF('النموذج'!$C$6:$BM$6,2031,'النموذج'!$C$103:$BM$103)
A40: التكاليف المركزية (تقنية، إدارة ومصروفات عمومية، علامة) | C40: =SUMIF('النموذج'!$C$6:$BM$6,2026,'النموذج'!$C$106:$BM$106) | D40: =SUMIF('النموذج'!$C$6:$BM$6,2027,'النموذج'!$C$106:$BM$106) | E40: =SUMIF('النموذج'!$C$6:$BM$6,2028,'النموذج'!$C$106:$BM$106) | F40: =SUMIF('النموذج'!$C$6:$BM$6,2029,'النموذج'!$C$106:$BM$106) | G40: =SUMIF('النموذج'!$C$6:$BM$6,2030,'النموذج'!$C$106:$BM$106) | H40: =SUMIF('النموذج'!$C$6:$BM$6,2031,'النموذج'!$C$106:$BM$106)
A41: EBITDA على مستوى المركز (قبل التكاليف المركزية) | C41: =SUMIF('النموذج'!$C$6:$BM$6,2026,'النموذج'!$C$107:$BM$107) | D41: =SUMIF('النموذج'!$C$6:$BM$6,2027,'النموذج'!$C$107:$BM$107) | E41: =SUMIF('النموذج'!$C$6:$BM$6,2028,'النموذج'!$C$107:$BM$107) | F41: =SUMIF('النموذج'!$C$6:$BM$6,2029,'النموذج'!$C$107:$BM$107) | G41: =SUMIF('النموذج'!$C$6:$BM$6,2030,'النموذج'!$C$107:$BM$107) | H41: =SUMIF('النموذج'!$C$6:$BM$6,2031,'النموذج'!$C$107:$BM$107)
A42: EBITDA | C42: =SUMIF('النموذج'!$C$6:$BM$6,2026,'النموذج'!$C$105:$BM$105) | D42: =SUMIF('النموذج'!$C$6:$BM$6,2027,'النموذج'!$C$105:$BM$105) | E42: =SUMIF('النموذج'!$C$6:$BM$6,2028,'النموذج'!$C$105:$BM$105) | F42: =SUMIF('النموذج'!$C$6:$BM$6,2029,'النموذج'!$C$105:$BM$105) | G42: =SUMIF('النموذج'!$C$6:$BM$6,2030,'النموذج'!$C$105:$BM$105) | H42: =SUMIF('النموذج'!$C$6:$BM$6,2031,'النموذج'!$C$105:$BM$105)
A43: EBITDA % من GMV | C43: =IF(C15>0,C42/C15,0) | D43: =IF(D15>0,D42/D15,0) | E43: =IF(E15>0,E42/E15,0) | F43: =IF(F15>0,F42/F15,0) | G43: =IF(G15>0,G42/G15,0) | H43: =IF(H15>0,H42/H15,0)
...

Sheet اقتصاديات الوحدة
A1: لكل طلب عميل (ج.م) — الطلب الواحد بيكسب كام وبيكلّف كام
B2: 2027 | C2: 2028 | D2: 2029 | E2: 2030 | F2: 2031
A3: متوسط قيمة الطلب (GMV للطلب) | B3: =IF('السنوي'!D$11>0,1*'السنوي'!D$15/'السنوي'!D$11,0) | C3: =IF('السنوي'!E$11>0,1*'السنوي'!E$15/'السنوي'!E$11,0) | D3: =IF('السنوي'!F$11>0,1*'السنوي'!F$15/'السنوي'!F$11,0) | E3: =IF('السنوي'!G$11>0,1*'السنوي'!G$15/'السنوي'!G$11,0) | F3: =IF('السنوي'!H$11>0,1*'السنوي'!H$15/'السنوي'!H$11,0)
A4: مجمل الربح للطلب (كل المصادر) | B4: =IF('السنوي'!D$11>0,1*'السنوي'!D$29/'السنوي'!D$11,0) | C4: =IF('السنوي'!E$11>0,1*'السنوي'!E$29/'السنوي'!E$11,0) | D4: =IF('السنوي'!F$11>0,1*'السنوي'!F$29/'السنوي'!F$11,0) | E4: =IF('السنوي'!G$11>0,1*'السنوي'!G$29/'السنوي'!G$11,0) | F4: =IF('السنوي'!H$11>0,1*'السنوي'!H$29/'السنوي'!H$11,0)
A6: مجمل الربح حسب المصدر
A7: عمولة السوق | B7: =IF('السنوي'!D$11>0,1*'السنوي'!D$19/'السنوي'!D$11,0) | C7: =IF('السنوي'!E$11>0,1*'السنوي'!E$19/'السنوي'!E$11,0) | D7: =IF('السنوي'!F$11>0,1*'السنوي'!F$19/'السنوي'!F$11,0) | E7: =IF('السنوي'!G$11>0,1*'السنوي'!G$19/'السنوي'!G$11,0) | F7: =IF('السنوي'!H$11>0,1*'السنوي'!H$19/'السنوي'!H$11,0)
A8: عمولة المطاعم | B8: =IF('السنوي'!D$11>0,1*'السنوي'!D$20/'السنوي'!D$11,0) | C8: =IF('السنوي'!E$11>0,1*'السنوي'!E$20/'السنوي'!E$11,0) | D8: =IF('السنوي'!F$11>0,1*'السنوي'!F$20/'السنوي'!F$11,0) | E8: =IF('السنوي'!G$11>0,1*'السنوي'!G$20/'السنوي'!G$11,0) | F8: =IF('السنوي'!H$11>0,1*'السنوي'!H$20/'السنوي'!H$11,0)
A9: رسوم التوصيل | B9: =IF('السنوي'!D$11>0,1*'السنوي'!D$21/'السنوي'!D$11,0) | C9: =IF('السنوي'!E$11>0,1*'السنوي'!E$21/'السنوي'!E$11,0) | D9: =IF('السنوي'!F$11>0,1*'السنوي'!F$21/'السنوي'!F$11,0) | E9: =IF('السنوي'!G$11>0,1*'السنوي'!G$21/'السنوي'!G$11,0) | F9: =IF('السنوي'!H$11>0,1*'السنوي'!H$21/'السنوي'!H$11,0)
A10: رسوم الخدمة | B10: =IF('السنوي'!D$11>0,1*'السنوي'!D$22/'السنوي'!D$11,0) | C10: =IF('السنوي'!E$11>0,1*'السنوي'!E$22/'السنوي'!E$11,0) | D10: =IF('السنوي'!F$11>0,1*'السنوي'!F$22/'السنوي'!F$11,0) | E10: =IF('السنوي'!G$11>0,1*'السنوي'!G$22/'السنوي'!G$11,0) | F10: =IF('السنوي'!H$11>0,1*'السنوي'!H$22/'السنوي'!H$11,0)
A11: توّا+ (موزعة على الطلب) | B11: =IF('السنوي'!D$11>0,1*'السنوي'!D$23/'السنوي'!D$11,0) | C11: =IF('السنوي'!E$11>0,1*'السنوي'!E$23/'السنوي'!E$11,0) | D11: =IF('السنوي'!F$11>0,1*'السنوي'!F$23/'السنوي'!F$11,0) | E11: =IF('السنوي'!G$11>0,1*'السنوي'!G$23/'السنوي'!G$11,0) | F11: =IF('السنوي'!H$11>0,1*'السنوي'!H$23/'السنوي'!H$11,0)
A12: رسوم التوصيل كخدمة (موزعة على الطلب) | B12: =IF('السنوي'!D$11>0,1*'السنوي'!D$24/'السنوي'!D$11,0) | C12: =IF('السنوي'!E$11>0,1*'السنوي'!E$24/'السنوي'!E$11,0) | D12: =IF('السنوي'!F$11>0,1*'السنوي'!F$24/'السنوي'!F$11,0) | E12: =IF('السنوي'!G$11>0,1*'السنوي'!G$24/'السنوي'!G$11,0) | F12: =IF('السنوي'!H$11>0,1*'السنوي'!H$24/'السنوي'!H$11,0)
A13: إعلانات التطبيق | B13: =IF('السنوي'!D$11>0,1*'السنوي'!D$25/'السنوي'!D$11,0) | C13: =IF('السنوي'!E$11>0,1*'السنوي'!E$25/'السنوي'!E$11,0) | D13: =IF('السنوي'!F$11>0,1*'السنوي'!F$25/'السنوي'!F$11,0) | E13: =IF('السنوي'!G$11>0,1*'السنوي'!G$25/'السنوي'!G$11,0) | F13: =IF('السنوي'!H$11>0,1*'السنوي'!H$25/'السنوي'!H$11,0)
A14: حوافز الموردين | B14: =IF('السنوي'!D$11>0,1*'السنوي'!D$26/'السنوي'!D$11,0) | C14: =IF('السنوي'!E$11>0,1*'السنوي'!E$26/'السنوي'!E$11,0) | D14: =IF('السنوي'!F$11>0,1*'السنوي'!F$26/'السنوي'!F$11,0) | E14: =IF('السنوي'!G$11>0,1*'السنوي'!G$26/'السنوي'!G$11,0) | F14: =IF('السنوي'!H$11>0,1*'السنوي'!H$26/'السنوي'!H$11,0)
A15: هامش المنتجات (مخزون مملوك) | B15: =IF('السنوي'!D$11>0,('السنوي'!D$18-'السنوي'!D$28)/'السنوي'!D$11,0) | C15: =IF('السنوي'!E$11>0,('السنوي'!E$18-'السنوي'!E$28)/'السنوي'!E$11,0) | D15: =IF('السنوي'!F$11>0,('السنوي'!F$18-'السنوي'!F$28)/'السنوي'!F$11,0) | E15: =IF('السنوي'!G$11>0,('السنوي'!G$18-'السنوي'!G$28)/'السنوي'!G$11,0) | F15: =IF('السنوي'!H$11>0,('السنوي'!H$18-'السنوي'!H$28)/'السنوي'!H$11,0)
A17: التكاليف المتغيرة لكل طلب
A18: المندوب (شامل التسليم المجزّأ والتوصيل كخدمة) | B18: =IF('السنوي'!D$11>0,-1*'السنوي'!D$34/'السنوي'!D$11,0) | C18: =IF('السنوي'!E$11>0,-1*'السنوي'!E$34/'السنوي'!E$11,0) | D18: =IF('السنوي'!F$11>0,-1*'السنوي'!F$34/'السنوي'!F$11,0) | E18: =IF('السنوي'!G$11>0,-1*'السنوي'!G$34/'السنوي'!G$11,0) | F18: =IF('السنوي'!H$11>0,-1*'السنوي'!H$34/'السنوي'!H$11,0)
A19: عروض العملاء | B19: =IF('السنوي'!D$11>0,-1*'السنوي'!D$35/'السنوي'!D$11,0) | C19: =IF('السنوي'!E$11>0,-1*'السنوي'!E$35/'السنوي'!E$11,0) | D19: =IF('السنوي'!F$11>0,-1*'السنوي'!F$35/'السنوي'!F$11,0) | E19: =IF('السنوي'!G$11>0,-1*'السنوي'!G$35/'السنوي'!G$11,0) | F19: =IF('السنوي'!H$11>0,-1*'السنوي'!H$35/'السنوي'!H$11,0)
A20: متغيرة أخرى (تجميع، تغليف، دفع، هالك، استرداد، دعم) | B20: =IF('السنوي'!D$11>0,-('السنوي'!D$33-'السنوي'!D$34-'السنوي'!D$35)/'السنوي'!D$11,0) | C20: =IF('السنوي'!E$11>0,-('السنوي'!E$33-'السنوي'!E$34-'السنوي'!E$35)/'السنوي'!E$11,0) | D20: =IF('السنوي'!F$11>0,-('السنوي'!F$33-'السنوي'!F$34-'السنوي'!F$35)/'السنوي'!F$11,0) | E20: =IF('السنوي'!G$11>0,-('السنوي'!G$33-'السنوي'!G$34-'السنوي'!G$35)/'السنوي'!G$11,0) | F20: =IF('السنوي'!H$11>0,-('السنوي'!H$33-'السنوي'!H$34-'السنوي'!H$35)/'السنوي'!H$11,0)
A21: المساهمة لكل طلب | B21: =IF('السنوي'!D$11>0,1*'السنوي'!D$36/'السنوي'!D$11,0) | C21: =IF('السنوي'!E$11>0,1*'السنوي'!E$36/'السنوي'!E$11,0) | D21: =IF('السنوي'!F$11>0,1*'السنوي'!F$36/'السنوي'!F$11,0) | E21: =IF('السنوي'!G$11>0,1*'السنوي'!G$36/'السنوي'!G$11,0) | F21: =IF('السنوي'!H$11>0,1*'السنوي'!H$36/'السنوي'!H$11,0)
A22: التكاليف الثابتة والاستحواذ لكل طلب | B22: =IF('السنوي'!D$11>0,-1*'السنوي'!D$38/'السنوي'!D$11,0) | C22: =IF('السنوي'!E$11>0,-1*'السنوي'!E$38/'السنوي'!E$11,0) | D22: =IF('السنوي'!F$11>0,-1*'السنوي'!F$38/'السنوي'!F$11,0) | E22: =IF('السنوي'!G$11>0,-1*'السنوي'!G$38/'السنوي'!G$11,0) | F22: =IF('السنوي'!H$11>0,-1*'السنوي'!H$38/'السنوي'!H$11,0)
A23: EBITDA لكل طلب | B23: =IF('السنوي'!D$11>0,1*'السنوي'!D$42/'السنوي'!D$11,0) | C23: =IF('السنوي'!E$11>0,1*'السنوي'!E$42/'السنوي'!E$11,0) | D23: =IF('السنوي'!F$11>0,1*'السنوي'!F$42/'السنوي'!F$11,0) | E23: =IF('السنوي'!G$11>0,1*'السنوي'!G$42/'السنوي'!G$11,0) | F23: =IF('السنوي'!H$11>0,1*'السنوي'!H$42/'السنوي'!H$11,0)

Sheet مصادر الإيراد
A1: مصادر الإيراد — مين بيدفع، التسعير، إمتى تبدأ، وبتكسب كام (مجمل الربح، ج.م)
A3: # | B3: المصدر | C3: الاسم | D3: مين بيدفع | E3: آلية التسعير | F3: يبدأ | G3: مجمل الربح 2027 | H3: مجمل الربح 2028 | I3: مجمل الربح 2029 | J3: مجمل الربح 2030 | K3: مجمل الربح 2031 | L3: الحصة 2031
